File: y.csv
Primary ID,ST-Hardness (g),ST-Rigidity at 2% deformation (g),ST-Rigidity at 4% deformation (g),ST-Peak stress (N/mp),3PBT-Hardness (g),3PBT-Deformation at hardness (mm),3PBT-Total work (mJ),3PBT-Maximum force (N),3PBT-Peak stress (N/mp),3PBT-Flexural stress (g/mmp) (Samaro 2021 Prasad 2019),3PBT-Flexural strain (%),3PBT-Breaking distance (mm),3PBT-Stiffness (N/mm) (Hu 2022)
BCS1_S1,8075.0,1260.0,5550.0,25462604.0,1532.0,5.79,15.65,15.0136,5404240.0,143.91684868373792,10.449792,5.79,2.593022452504318
BCS1_S3,1700.0,350.0,875.0,5808817.0,1111.5,6.48,12.08,10.8927,4192343.0,115.08579612450262,11.321856,6.48,1.680972222222222
BCS1_S7,8690.0,2485.0,6535.0,32402960.0,755.0,5.97,7.15,7.399,3594185.0,110.8481198642743,9.284544,5.97,1.2393634840871022
BCS1_S9,8680.0,2165.0,6120.0,31643764.0,707.5,2.03,7.68,6.9334999999999996,3833262.0,125.75408559398917,2.9621759999999995,2.03,3.4155172413793102
BCS1_S12,5925.0,660.0,3290.0,18865064.0,1318.5,1.59,11.23,12.9213,4040646.0,99.85100699376969,3.083328,1.59,8.126603773584906
BCS1_S14,6500.0,1585.0,5515.0,20496214.0,712.0,0.99,4.13,6.9776,2312031.0,59.02529996790085,1.862784,0.99,7.048080808080808
BCS1_S17,4705.0,1030.0,3375.0,21068624.0,822.0,1.77,8.28,8.0556,3237376.0,90.97838724136697,3.024576,1.77,4.5511864406779665
BCS1_S19,3835.0,300.0,2250.0,16789510.0,868.0,1.8,8.79,8.5064,3460233.0,97.70715084423902,3.05856,1.8,4.725777777777777
BCS1_S22,5275.0,1515.0,4055.0,19447398.0,611.0,1.03,3.61,5.9878,2178859.0,58.323397366903436,1.849056,1.03,5.813398058252427
BCS1_S24,6150.0,1510.0,4540.0,22931900.0,677.0,1.32,4.93,6.6346,2634564.0,73.68108271562438,2.268288,1.32,5.0262121212121205
BCS1_S27,7040.0,2465.0,6680.0,25105024.0,640.0,1.11,3.9,6.272,2442123.0,67.37063994192539,1.9287360000000005,1.11,5.6504504504504505
BCS1_S29,7705.0,2670.0,6025.0,26889764.0,668.5,1.34,5.15,6.5512999999999995,2697838.0,76.54024207470556,2.264064,1.34,4.889029850746268
BCS1_S32,8685.0,2965.0,6925.0,39799416.0,857.5,2.63,7.28,8.4035,3578384.0,103.37659958434648,4.367904,2.63,3.1952471482889733
BCS1_S34,6105.0,710.0,3760.0,32537824.0,864.0,1.27,6.41,8.4672,3515745.0,100.62966333030027,2.1336,1.27,6.667086614173228
BCS1_S37,6635.0,1505.0,4575.0,23921736.0,1494.0,1.53,10.48,14.6412,4069760.0,95.15589550266193,3.1432320000000002,1.53,9.569411764705881
BCS1_S39,3140.0,90.0,1275.0,10298622.0,826.5,1.38,6.73,8.0997,3570571.0,105.00803146727583,2.2521599999999995,1.38,5.869347826086957
BCS1_S42,5355.0,1960.0,5355.0,18688474.0,538.0,0.74,2.72,5.2724,1857739.0,48.96073130936804,1.3497599999999998,0.74,7.124864864864866
BCS1_S44,5470.0,195.0,3225.0,18888160.0,533.5,0.84,2.52,5.2283,1881960.0,50.11725768457845,1.516032,0.84,6.224166666666667
BCS1_S47,5420.0,1975.0,4385.0,20926000.0,381.0,1.34,2.79,3.7338,1877555.0,59.16434024979491,2.045376,1.34,2.786417910447761
BCS1_S49,3375.0,320.0,2120.0,11069379.0,405.0,1.04,2.66,3.969,1668779.0,47.98811618373428,1.737216,1.04,3.8163461538461534
BCS1_S52,5390.0,1370.0,4125.0,20329940.0,763.0,1.53,6.36,7.477399999999999,2945856.0,81.66452604999431,2.64384,1.53,4.88718954248366
BCS1_S54,6595.0,2580.0,5425.0,28491126.0,620.0,1.38,5.02,6.076,2678468.0,78.77190503292317,2.2521599999999995,1.38,4.402898550724638
BCS1_S57,6550.0,1180.0,4450.0,17818094.0,1794.5,1.42,14.07,17.5861,4835223.0,131.9409,2.780928,1.42,12.38458
BCS1_S59,8630.0,2230.0,6145.0,25414832.0,1280.0,1.42,10.13,12.544,4224057.0,132.5325,2.481024,1.42,8.833803
BCS1_S62,9020.0,2780.0,7085.0,34021532.0,1290.0,6.14,13.56,12.642,4501985.0,119.2699,11.14042,6.14,2.058958
BCS1_S64,7995.0,1590.0,5650.0,25961644.0,1776.0,6.52,24.62,17.4048,6068505.0,159.0997,11.95507,6.52,2.669448
BCS1_S67,1670.0,225.0,1095.0,6020995.0,792.5,4.85,77.15,7.7665,2889134.0,78.12868,8.6136,4.85,1.60134
BCS1_S69,1750.0,240.0,950.0,6810174.0,266.5,1.36,2.15,2.6117,1037092.0,29.00444,2.337024,1.36,1.920368
BCS1_S72,3060.0,215.0,1540.0,9261836.0,1824.0,1.96,19.34,17.8752,6104891.0,158.3723,3.631488,1.96,9.12
BCS1_S74,6765.0,1330.0,4465.0,23115676.0,1767.0,2.59,25.65,17.3166,5854172.0,151.0629,4.823616,2.59,6.685946
BCS1_S77,6320.0,2400.0,4830.0,24594456.0,1225.0,5.43,116.0,12.005,4767122.0,133.3225,9.330912,5.43,2.210866
BCS1_S79,5310.0,1590.0,4070.0,20912976.0,1071.5,4.53,104.95,10.5007,4360094.0,124.7971,7.6104,4.53,2.318035
BCS1_S82,1535.0,75.0,880.0,5473894.0,391.0,1.33,3.03,3.8318,1775185.0,53.35547,2.119488,1.33,2.881053
BCS1_S84,3000.0,535.0,2040.0,12681013.0,290.5,3.51,1.73,2.8469,1318904.0,39.64134,5.593536,3.51,0.811083
BCS1_S87,6385.0,1660.0,4735.0,21153872.0,1443.0,4.61,46.84,14.1414,5823455.0,165.217,7.789056,4.61,3.067549
BCS1_S89,5125.0,995.0,3250.0,16809056.0,1500.0,2.41,20.2,14.7,4919724.0,126.274,4.51152,2.41,6.099585
BCS1_S92,5775.0,1050.0,3895.0,15908259.0,1624.5,4.8,69.46,15.9201,5073536.0,126.7524,9.216,4.8,3.316688
BCS1_S94,1810.0,210.0,965.0,5130068.0,1793.0,3.05,31.39,17.5714,4981111.0,117.4625,6.20736,3.05,5.761115
BCS1_S97,1920.0,700.0,1440.0,4954939.0,573.0,1.33,4.31,5.6154,2088926.0,56.48926,2.36208,1.33,4.222105
BCS1_S99,2440.0,575.0,1850.0,7385255.0,367.5,0.94,2.05,3.6015,1354866.0,36.82394,1.660416,0.94,3.831383
BCS1_S102,4930.0,1150.0,3375.0,18811978.0,1145.5,2.41,15.43,11.2259,4040834.0,107.6088,4.349568,2.41,4.65805
BCS1_S104,5180.0,1075.0,3335.0,21895882.0,1772.0,4.38,162.03,17.3656,5156494.0,124.7036,8.703936,4.38,3.964749
BCS1_S107,3290.0,895.0,2230.0,16051681.0,1176.0,3.9,29.51,11.5248,4060782.0,107.022,7.1136,3.9,2.955077
BCS1_S109,4395.0,1135.0,3090.0,18109340.0,984.5,4.84,95.65,9.6481,3549503.0,95.49999,8.642304,4.84,1.993409
BCS1_S112,3905.0,990.0,2675.0,11819435.0,1561.5,3.15,28.81,15.3027,4876778.0,121.83678343949045,6.048,3.15,4.858
BCS1_S114,4670.0,1590.0,3640.0,14005216.0,1323.5,2.2,16.69,12.9703,3817383.0,91.80373782539304,4.3929599999999995,2.2,5.895590909090909
BCS1_S117,2170.0,530.0,1615.0,6314668.0,1301.0,4.27,128.29,12.7498,4481975.0,75.23620806072289,9.059231999999998,4.27,2.9859016393442626
BCS1_S119,2365.0,825.0,1875.0,7316318.0,1285.0,5.17,86.71,12.593,5179028.0,67.67449286251586,11.316096,5.17,2.4357833655706
BCS1_S122,1675.0,545.0,1290.0,4096294.0,770.5,4.72,76.55,7.5508999999999995,2004250.0,45.78958651487927,9.923328,4.72,1.5997669491525424
BCS1_S124,1810.0,590.0,1340.0,4671062.0,570.5,5.66,56.92,5.5908999999999995,1631106.0,39.007059582886875,11.356224,5.66,0.9877915194346288
BCS1_S127,6815.0,1370.0,4625.0,19831548.0,2390.5,1.94,25.49,23.4269,3321470.0,114.97716195207533,4.37664,1.94,12.075721649484537
BCS1_S129,7905.0,1140.0,5210.0,22601040.0,1318.5,3.21,22.64,12.9213,4972454.0,127.89916959346147,5.731776,3.21,4.025327102803739
BCS1_S132,3605.0,515.0,2415.0,11047804.0,1523.5,2.82,23.67,14.930299999999999,4318044.0,102.68594345027465,5.68512,2.82,5.294432624113475
BCS1_S134,4660.0,900.0,3060.0,14104626.0,1269.0,2.82,19.37,12.4362,3737129.0,90.61213936343758,5.576832,2.82,4.41
BCS1_S137,2375.0,235.0,1370.0,9353732.0,607.5,2.91,9.82,5.9535,2720338.0,81.41853658441322,4.665311999999999,2.91,2.0458762886597937
BCS1_S139,2970.0,375.0,1690.0,9187934.0,546.0,3.06,9.11,5.3508,2561929.0,78.69665132232473,4.788288,3.06,1.748627450980392
BCS1_S142,3375.0,1010.0,2610.0,8619126.0,706.0,1.94,8.03,6.9188,2437850.0,64.24958420894765,3.53856,1.94,3.56639175257732
BCS1_S144,2650.0,650.0,1980.0,6715148.0,502.5,1.54,4.77,4.9245,1940095.0,53.782993892689575,2.66112,1.54,3.1977272727272728
BCS1_S147,5155.0,1075.0,3345.0,15181165.0,1001.0,2.33,12.48,9.8098,3067643.0,75.80649070971819,4.518336,2.33,4.210214592274678
BCS1_S149,4650.0,1115.0,3235.0,14074359.0,738.5,3.02,12.73,7.237299999999999,2446693.0,63.13522508787288,5.624447999999999,3.02,2.396456953642384
BCS1_S152,5435.0,1210.0,3885.0,16974248.0,784.0,1.73,7.94,7.683199999999999,2520791.0,64.00940754340488,3.271776,1.73,4.441156069364162
BCS1_S154,5950.0,1420.0,4125.0,18234240.0,619.0,1.43,5.07,6.066199999999999,2050783.0,52.91903091319338,2.663232,1.43,4.2420979020979015
BCS1_S157,6525.0,1225.0,4640.0,16973048.0,1434.0,2.15,17.62,14.0532,4136099.0,99.46850022033519,4.29312,2.15,6.536372093023256
BCS1_S159,6165.0,1100.0,3725.0,16518578.0,1679.5,2.41,21.6,16.4591,5083416.0,125.31940311849448,4.6966079999999994,2.41,6.829502074688796
BCS1_S162,830.0,280.0,615.0,3308748.0,160.5,5.46,15.63,1.5729,889247.0,29.68435951875442,7.8624,5.46,0.28807692307692306
BCS1_S164,1225.0,435.0,945.0,4883393.0,198.5,6.79,19.15,1.9453,931397.0,28.610412614434907,10.624992,6.79,0.28649484536082476
BCS2_S2,9415.0,1645.0,6800.0,38793952.0,862.5,1.83,8.43,8.4525,4208077.0,131.43940336385347,2.8108800000000005,1.83,4.618852459016393
BCS2_S4,10320.0,2530.0,7580.0,41993624.0,939.0,1.92,9.63,9.2022,4056583.0,119.30132068695946,3.13344,1.92,4.7928125
BCS2_S7,9340.0,2490.0,6970.0,35228504.0,1242.0,1.71,11.98,12.1716,4381244.0,116.67410317571965,3.0862079999999996,1.71,7.117894736842105
BCS2_S9,8755.0,2905.0,7910.0,31220808.0,1115.0,1.51,8.91,10.927,4157572.0,113.56591947514886,2.652768,1.51,7.236423841059603
BCS2_S12,10905.0,2035.0,8185.0,790411584.0,1110.5,2.36,10.67,10.8829,4287514.0,118.85774073200352,4.07808,2.36,4.611398305084745
BCS2_S14,9265.0,2420.0,6285.0,399497536.0,1075.0,2.05,11.03,10.535,4374336.0,125.20473157415833,3.444,2.05,5.139024390243903
BCS2_S17,9925.0,2275.0,6860.0,37435000.0,1383.0,1.98,15.52,13.5534,5513251.0,155.67855946726104,3.3644160000000003,1.98,6.845151515151515
BCS2_S19,10635.0,2715.0,7580.0,43820892.0,1089.0,2.62,15.01,10.6722,4990393.0,151.3221385832851,4.15008,2.62,4.073358778625954
BCS2_S22,5435.0,1000.0,3560.0,18006468.0,1278.0,1.98,13.6,12.5244,4109147.0,104.34186586794826,3.7445760000000003,1.98,6.325454545454545
BCS2_S24,8435.0,1985.0,6120.0,28231772.0,1242.0,1.82,12.56,12.1716,4288683.0,113.02830536474929,3.3196799999999995,1.82,6.687692307692307
BCS2_S27,6400.0,1215.0,4055.0,28019000.0,760.5,2.24,9.68,7.4529,3805080.0,120.35229626090091,3.3976320000000007,2.24,3.3271874999999995
BCS2_S29,5045.0,965.0,3580.0,26177010.0,767.5,1.72,7.31,7.5215,3202810.0,92.52657747053752,2.856576,1.72,4.37296511627907
BCS2_S32,7770.0,1590.0,5215.0,40316228.0,1056.5,3.05,16.61,10.3537,4299056.0,123.05004549590535,5.124,3.05,3.3946557377049182
BCS2_S34,10540.0,2540.0,7755.0,57106128.0,1191.0,3.56,21.25,11.6718,4846357.0,138.71519563239306,5.9808,3.56,3.2785955056179774
BCS2_S37,6465.0,1345.0,4450.0,27565214.0,833.5,2.94,13.08,8.1683,3819553.0,115.81910239593033,4.65696,2.94,2.7783333333333333
BCS2_S39,7185.0,1460.0,4735.0,27100300.0,885.0,3.94,20.41,8.673,3909408.0,116.50427156000404,6.354432,3.94,2.201269035532995
BCS2_S42,8655.0,1750.0,5975.0,28674512.0,669.5,2.63,10.21,6.5611,3473837.0,112.22300925748746,3.91344,2.63,2.4947148288973384
BCS2_S44,8170.0,1985.0,5515.0,28211384.0,719.0,2.1,8.27,7.0462,3176118.0,94.65149293970951,3.3868799999999997,2.1,3.3553333333333333
BCS2_S47,7390.0,1560.0,4780.0,30838784.0,1247.0,2.12,14.23,12.2206,4971095.0,140.36960495710377,3.602304,2.12,5.7644339622641505
BCS2_S49,9450.0,2490.0,6990.0,37671888.0,1148.5,2.6,15.61,11.2553,4961646.0,145.91860150050368,4.2432,2.6,4.328961538461538
BCS2_S52,8185.0,1715.0,5805.0,32235916.0,1224.0,2.43,15.27,11.995199999999999,4725724.0,131.00574034756625,4.19904,2.43,4.9362962962962955
BCS2_S54,7625.0,1360.0,5290.0,25520720.0,887.5,2.0,8.28,8.6975,3271956.0,88.9285714753125,3.5328,2.0,4.34875
BCS2_S57,7500.0,2310.0,5540.0,38507788.0,1290.0,1.8200000000000003,13.08,12.642,5572942.0,163.89638305237244,2.9702400000000004,1.8200000000000003,6.946153846153845
BCS2_S59,7820.0,2260.0,5845.0,42842460.0,1057.5,2.3299999999999996,14.129999999999999,10.3635,5487054.0,177.2603917696684,3.4670399999999995,2.3299999999999996,4.447854077253219
BCS2_S62,7400.0,2020.0,5510.0,20557850.0,1202.0,1.61,10.81,11.7796,4481975.0,122.42711677948783,2.8284480000000003,1.61,7.316521739130435
BCS2_S64,6445.0,1820.0,4715.0,21794434.0,1484.0,1.58,13.11,14.543199999999999,5179028.0,137.20657128868362,2.8667519999999995,1.58,9.204556962025315
BCS2_S67,2210.0,465.0,1555.0,8532558.0,657.0,1.5299999999999998,4.86,6.4386,2556734.0,71.50438898695009,2.6291519999999995,1.5299999999999998,4.208235294117648
BCS2_S69,2105.0,860.0,1870.0,7118275.0,734.0,1.4200000000000004,5.68,7.1932,3024404.0,86.97105500953325,2.3719680000000007,1.4200000000000004,5.0656338028169
BCS2_S72,4380.0,630.0,2560.0,16331987.0,779.0,1.2299999999999998,5.62,7.6342,3321470.0,97.24685159687536,2.0191679999999996,1.2299999999999998,6.206666666666668
BCS2_S74,3535.0,525.0,2240.0,14565760.0,1546.5,1.6600000000000001,13.870000000000001,15.1557,4972454.0,126.26345505851485,3.1393920000000004,1.6600000000000001,9.129939759036143
BCS2_S77,4040.0,460.0,2650.0,15721772.0,973.0,1.3299999999999996,7.51,9.5354,3395683.0,89.96091230720293,2.4131519999999993,1.3299999999999996,7.169473684210527
BCS2_S79,4865.0,1805.0,4745.0,22827440.0,750.0,1.4200000000000004,5.9399999999999995,7.35,3570382.0,110.11402635523937,2.2083840000000006,1.4200000000000004,5.176056338028167
BCS2_S83,115.0,85.0,35.0,490333.0,395.5,0.8399999999999999,2.0200000000000005,3.8758999999999997,1310314.0,33.811755615780264,1.5644159999999996,0.8399999999999999,4.614166666666667
BCS2_S85,365.0,310.0,345.0,1392773.0,590.5,2.29,4.08,5.7869,2353995.0,66.47012969299904,3.891168,2.29,2.5270305676855895
BCS2_S88,625.0,610.0,495.0,1970790.0,889.5,1.2700000000000002,6.5,8.7171,3316736.0,90.59810347367257,2.2311360000000002,1.2700000000000002,6.863858267716535
BCS2_S90,150.0,55.0,55.0,468471.0,915.5,2.3200000000000003,9.99,8.9719,3955061.0,116.31561138329221,3.7862400000000007,2.3200000000000003,3.8671982758620684
BCS2_S93,440.0,405.0,260.0,1659587.0,476.5,1.2399999999999998,3.59,4.6697,1963390.0,56.460092250739216,2.0712959999999994,1.2399999999999998,3.765887096774194
BCS2_S95,290.0,60.0,210.0,1210182.0,496.5,1.0299999999999998,2.7,4.8656999999999995,2173661.0,64.20747070212003,1.6710719999999997,1.0299999999999998,4.723980582524272
BCS2_S98,1470.0,1010.0,1345.0,6267728.0,307.5,0.7100000000000002,1.4799999999999998,3.0135,1121020.0,30.31491523254072,1.2609600000000003,0.7100000000000002,4.244366197183098
BCS2_S100,2320.0,1820.0,2170.0,9681459.0,353.5,0.8100000000000002,1.8799999999999997,3.4642999999999997,1392229.0,39.125133685916325,1.3841280000000005,0.8100000000000002,4.276913580246912
BCS2_S103,4335.0,2430.0,4160.0,15803653.0,801.5,1.7299999999999998,7.49,7.854699999999999,3760780.0,115.52264841546386,2.7071039999999993,1.7299999999999998,4.540289017341041
BCS2_S105,5430.0,2040.0,4965.0,17632488.0,911.0,1.9299999999999997,9.43,8.9278,4024260.0,119.92699592221886,3.1127039999999995,1.9299999999999997,4.625803108808291
BCS2_S108,5205.0,2245.0,5205.0,22001556.0,911.0,2.13,10.31,8.9278,4174700.0,126.58812511420818,3.3739199999999996,2.13,4.191455399061033
BCS2_S110,5405.0,2030.0,5085.0,25361216.0,815.0,1.94,8.27,7.987,3474965.0,101.740929462713,3.184704,1.94,4.117010309278351
BCS2_S113,10175.0,2050.0,7075.0,40562056.0,1046.0,2.09,11.45,10.2508,4861496.0,148.02210081384607,3.290496,2.09,4.904688995215311
BCS2_S115,11670.0,3195.0,8755.0,64657404.0,1264.5,1.64,11.48,12.3921,4769427.0,130.92756563151917,2.865408,1.64,7.556158536585365
BCS2_S123,4540.0,945.0,2310.0,16368453.0,243.0,0.39,0.59,2.3813999999999997,916545.0,25.160457452320408,0.681408,0.39,6.106153846153846
BCS2_S125,4435.0,3240.0,0.0,21319848.0,331.5,0.51,1.15,3.2487,1208515.0,32.680957397031705,0.90576,0.51,6.37
BCS2_S128,10370.0,3150.0,7775.0,39113448.0,1976.5,2.28,24.86,19.369699999999998,7048307.0,188.66807675234801,4.093056,2.28,8.495482456140351
BCS2_S130,7290.0,2020.0,5560.0,27817308.0,1756.5,2.19,21.22,17.2137,6065275.0,159.85041736971183,3.99456,2.19,7.86013698630137
BCS2_S133,11775.0,3615.0,8805.0,38236192.0,1221.5,2.01,13.0,11.970699999999999,5097371.0,147.2589112446405,3.3382079999999994,2.01,5.955572139303483
BCS2_S135,9295.0,2690.0,7180.0,30183050.0,775.5,1.75,7.66,7.5999,3553765.0,107.75970474870302,2.772,1.75,4.3427999999999995
BCS2_S138,3835.0,1235.0,3565.0,13980856.0,415.5,1.35,2.55,4.0719,1164189.0,27.60896241393398,2.7345599999999997,1.35,3.0162222222222224
BCS2_S140,8795.0,2335.0,6680.0,23123188.0,531.5,1.24,3.52,5.208699999999999,1533010.0,36.867160297843895,2.476032,1.24,4.200564516129032
BCS2_S143,8215.0,2005.0,6395.0,42178864.0,871.0,2.63,12.56,8.5358,4519361.0,145.9988664126536,3.91344,2.63,3.245551330798479
BCS2_S145,9050.0,2915.0,7070.0,51598944.0,1465.0,2.86,20.58,14.357,5525670.0,151.68753155411275,4.996992,2.86,5.01993006993007
BCS2_S148,10160.0,3750.0,7640.0,39537920.0,798.0,3.19,13.33,7.820399999999999,3836131.0,119.35804219306789,4.930464,3.19,2.4515360501567396
BCS2_S150,8750.0,2565.0,6195.0,27068828.0,653.0,4.0,16.15,6.3994,3766907.0,128.31800542335168,5.6448,4.0,1.59985
BCS2_S153,7240.0,1755.0,4945.0,21515196.0,1168.0,1.61,10.28,11.446399999999999,3579427.0,88.45352762132951,3.1221120000000004,1.61,7.109565217391303
BCS2_S155,7485.0,1350.0,5370.0,23155450.0,478.0,2.31,4.25,4.6844,2355567.0,74.22717753123877,3.5259840000000002,2.31,2.027878787878788
BCS2_S158,10730.0,3120.0,7745.0,44212336.0,1551.0,1.89,14.65,15.1998,4890712.0,122.85108370423809,3.6106559999999996,1.89,8.042222222222222
BCS2_S160,9620.0,2560.0,6955.0,43675912.0,1323.0,1.99,14.04,12.965399999999999,4769926.0,128.3356855306405,3.553344,1.99,6.515276381909548
BCS2_S163,10180.0,2425.0,7160.0,34784564.0,1587.5,1.73,15.89,15.5575,4760874.0,116.72117611238569,3.388032,1.73,8.992774566473988
BCS2_S165,10820.0,3440.0,8260.0,42106332.0,1130.5,2.47,15.14,11.078899999999999,4820182.0,141.12652853692887,4.054752000000001,2.47,4.485384615384615
PS-S3,2540.0,785.0,1975.0,9806650.0,532.0,1.59,4.89,5.2136,2350060.0,70.0342,2.56435,1.59,3.27899
PS-S5,3080.0,570.0,2070.0,13132400.0,753.0,1.61,6.69,7.3794,2572960.0,67.4561,2.9521,1.61,4.58348
PS-S8,1295.0,420.0,940.0,4721050.0,326.0,6.12,15.19,3.1948,1515150.0,46.1331,9.63533,6.12,0.522026
PS-S10,1645.0,445.0,1150.0,6557700.0,196.0,5.92,16.09,1.9208,1073800.0,35.5346,8.58163,5.92,0.324459
PS-S13,1820.0,435.0,1080.0,7082580.0,374.0,1.35,2.83,3.6652,1455430.0,40.7042,2.31984,1.35,2.71496
PS-S15,2045.0,440.0,1370.0,7713310.0,422.5,1.66,3.87,4.1405,1575400.0,43.0328,2.91629,1.66,2.49428
PS-S18,1480.0,425.0,1010.0,5004770.0,206.5,1.14,1.3,2.0237,769990.0,21.0326,2.00275,1.14,1.77518
PS-S20,1650.0,420.0,1120.0,5697530.0,209.0,2.86,1.68,2.0482,833167.0,23.5263,4.85971,2.86,0.716154
BCS1_S3,1700.0,350.0,875.0,5808817.0,1111.5,6.48,12.08,10.8927,4192343.0,115.08579612450262,11.321856,6.48,1.680972222222222
BCS1_S6,3570.0,415.0,2190.0,13622467.0,750.5,6.05,6.98,7.3549,3607790.0,112.2533968244329,9.35088,6.05,1.2156859504132231
BCS1_S9,8680.0,2165.0,6120.0,31643764.0,707.5,2.03,7.68,6.9334999999999996,3833262.0,125.75408559398917,2.9621759999999995,2.03,3.4155172413793102
BCS1_S11,7345.0,1255.0,4785.0,25362620.0,1215.5,3.58,10.93,11.9119,3724995.0,92.05073871894352,6.942336,3.58,3.3273463687150837
BCS1_S14,6500.0,1585.0,5515.0,20496214.0,712.0,0.99,4.13,6.9776,2312031.0,59.02529996790085,1.862784,0.99,7.048080808080808
BCS1_S16,5200.0,960.0,3750.0,21426294.0,820.0,1.67,7.77,8.036,3165926.0,87.76528356617999,2.8857600000000003,1.67,4.811976047904191
BCS1_S19,3835.0,300.0,2250.0,16789510.0,868.0,1.8,8.79,8.5064,3460233.0,97.70715084423902,3.05856,1.8,4.725777777777777
BCS1_S21,4615.0,1095.0,3170.0,16457342.0,686.5,1.25,4.72,6.7277,2619558.0,72.2655380002059,2.172,1.25,5.38216
BCS1_S24,6150.0,1510.0,4540.0,22931900.0,677.0,1.32,4.93,6.6346,2634564.0,73.68108271562438,2.268288,1.32,5.0262121212121205
BCS1_S26,4665.0,540.0,2655.0,17006700.0,543.0,1.13,3.68,5.3214,2191363.0,62.171056763747366,1.9092479999999996,1.13,4.709203539823009
BCS1_S29,7705.0,2670.0,6025.0,26889764.0,668.5,1.34,5.15,6.5512999999999995,2697838.0,76.54024207470556,2.264064,1.34,4.889029850746268
BCS1_S31,7255.0,1210.0,4905.0,32487328.0,893.0,1.42,7.27,8.7514,3559894.0,100.52129689390031,2.412864,1.42,6.162957746478874
BCS1_S34,6105.0,710.0,3760.0,32537824.0,864.0,1.27,6.41,8.4672,3515745.0,100.62966333030027,2.1336,1.27,6.667086614173228
BCS1_S36,5220.0,615.0,3045.0,20558520.0,1368.5,1.14,9.12,13.411299999999999,3834400.0,90.93348992411227,2.3091839999999997,1.14,11.764298245614036
BCS1_S39,3140.0,90.0,1275.0,10298622.0,826.5,1.38,6.73,8.0997,3570571.0,105.00803146727583,2.2521599999999995,1.38,5.869347826086957
BCS1_S41,5980.0,1600.0,5980.0,19418466.0,530.5,0.74,2.51,5.1989,1775573.0,46.06169173349649,1.3710719999999998,0.74,7.025540540540541
BCS1_S44,5470.0,195.0,3225.0,18888160.0,533.5,0.84,2.52,5.2283,1881960.0,50.11725768457845,1.516032,0.84,6.224166666666667
BCS1_S46,4375.0,835.0,3130.0,16501575.0,392.5,1.24,2.81,3.8465,1868500.0,57.62634045924194,1.928448,1.24,3.102016129032258
BCS1_S49,3375.0,320.0,2120.0,11069379.0,405.0,1.04,2.66,3.969,1668779.0,47.98811618373428,1.737216,1.04,3.8163461538461534
BCS1_S51,6400.0,2090.0,5165.0,23594948.0,649.5,1.74,6.1,6.3651,2805912.0,82.51992309497356,2.83968,1.74,3.658103448275862
BCS1_S54,6595.0,2580.0,5425.0,28491126.0,620.0,1.38,5.02,6.076,2678468.0,78.77190503292317,2.2521599999999995,1.38,4.402898550724638
BCS1_S56,9510.0,1465.0,7110.0,24737730.0,1597.5,1.3,11.99,15.6555,7512651.0,119.2008,2.53344,1.3,12.04269
BCS1_S59,8630.0,2230.0,6145.0,25414832.0,1280.0,1.42,10.13,12.544,4224057.0,132.5325,2.481024,1.42,8.833803
BCS1_S61,4935.0,825.0,3175.0,20081252.0,1730.5,5.94,23.1,16.9589,5733246.0,147.9425,11.06266,5.94,2.855034
BCS1_S64,7995.0,1590.0,5650.0,25961644.0,1776.0,6.52,24.62,17.4048,6068505.0,159.0997,11.95507,6.52,2.669448
BCS1_S66,4100.0,1225.0,3110.0,15955264.0,768.5,10.64,53.33,7.5313,2681997.0,71.0534,19.30522,10.64,0.707829
BCS1_S69,1750.0,240.0,950.0,6810174.0,266.5,1.36,2.15,2.6117,1037092.0,29.00444,2.337024,1.36,1.920368
BCS1_S71,9220.0,2050.0,6930.0,30239904.0,1899.0,1.56,15.15,18.6102,5477302.0,131.7229,3.115008,1.56,11.92962
BCS1_S74,6765.0,1330.0,4465.0,23115676.0,1767.0,2.59,25.65,17.3166,5854172.0,151.0629,4.823616,2.59,6.685946
BCS1_S76,3490.0,595.0,2435.0,12051130.0,738.5,5.66,68.02,7.2373,3190401.0,93.8275,9.23712,5.66,1.278675
BCS1_S79,5310.0,1590.0,4070.0,20912976.0,1071.5,4.53,104.95,10.5007,4360094.0,124.7971,7.6104,4.53,2.318035
BCS1_S81,3425.0,1005.0,2725.0,11703058.0,354.5,1.45,2.88,3.4741,1587423.0,47.5109,2.32464,1.45,2.395931
BCS1_S84,3000.0,535.0,2040.0,12681013.0,290.5,3.51,1.73,2.8469,1318904.0,39.64134,5.593536,3.51,0.811083
BCS1_S86,6330.0,1420.0,3990.0,21857780.0,1924.5,4.0,59.34,18.8601,7258807.0,199.2646,6.9888,4.0,4.715025
BCS1_S89,5125.0,995.0,3250.0,16809056.0,1500.0,2.41,20.2,14.7,4919724.0,126.274,4.51152,2.41,6.099585
BCS1_S91,2550.0,335.0,1670.0,7227444.0,1628.0,5.22,155.5,15.9544,5339541.0,137.0494,9.77184,5.22,3.056398
BCS1_S94,1810.0,210.0,965.0,5130068.0,1793.0,3.05,31.39,17.5714,4981111.0,117.4625,6.20736,3.05,5.761115
BCS1_S96,2675.0,605.0,1985.0,8096540.0,139.0,0.36,0.27,1.3622,451366.0,11.5232,0.677376,0.36,3.783889
BCS1_S99,2440.0,575.0,1850.0,7385255.0,367.5,0.94,2.05,3.6015,1354866.0,36.82394,1.660416,0.94,3.831383
BCS1_S101,4500.0,725.0,2760.0,15376280.0,1032.5,1.51,8.59,10.1185,2926406.0,69.59188,3.04416,1.51,6.700993
BCS1_S104,5180.0,1075.0,3335.0,21895882.0,1772.0,4.38,162.03,17.3656,5156494.0,124.7036,8.703936,4.38,3.964749
BCS1_S106,7275.0,2470.0,5500.0,29976210.0,1393.5,4.16,129.7,13.6563,4019284.0,96.65924,8.306688,4.16,3.282764
BCS1_S109,4395.0,1135.0,3090.0,18109340.0,984.5,4.84,95.65,9.6481,3549503.0,95.49999,8.642304,4.84,1.993409
BCS1_S111,4645.0,1395.0,3575.0,14059225.0,1511.5,3.56,147.41,14.8127,4491743.0,109.51484469849494,7.006079999999999,3.56,4.1608707865168535
BCS1_S114,4670.0,1590.0,3640.0,14005216.0,1323.5,2.2,16.69,12.9703,3817383.0,91.80373782539304,4.3929599999999995,2.2,5.895590909090909
BCS1_S116,2155.0,425.0,1615.0,7139639.0,1366.0,4.18,133.31,13.3868,4017755.0,74.85650878526556,9.0288,4.18,3.202583732057416
BCS1_S119,2365.0,825.0,1875.0,7316318.0,1285.0,5.17,86.71,12.593,5179028.0,67.67449286251586,11.316096,5.17,2.4357833655706
BCS1_S121,1365.0,440.0,1100.0,3687625.0,559.5,6.1,57.77,5.483099999999999,1628137.0,39.37453861025743,12.12192,6.1,0.8988688524590164
BCS1_S124,1810.0,590.0,1340.0,4671062.0,570.5,5.66,56.92,5.5908999999999995,1631106.0,39.007059582886875,11.356224,5.66,0.9877915194346288
BCS1_S126,4815.0,1140.0,3340.0,14179886.0,1232.0,2.56,17.44,12.073599999999999,4558206.0,129.68848188820635,4.448256,2.56,4.71625
BCS1_S129,7905.0,1140.0,5210.0,22601040.0,1318.5,3.21,22.64,12.9213,4972454.0,127.89916959346147,5.731776,3.21,4.025327102803739
BCS1_S131,7280.0,1630.0,5265.0,22736436.0,1302.5,2.57,18.21,12.7645,3790256.0,91.66279989251171,5.107104,2.57,4.966731517509728
BCS1_S134,4660.0,900.0,3060.0,14104626.0,1269.0,2.82,19.37,12.4362,3737129.0,90.61213936343758,5.576832,2.82,4.41
BCS1_S136,3855.0,615.0,2630.0,13172347.0,824.5,2.5,10.98,8.0801,2625189.0,66.30121887111783,4.752,2.5,3.23204
BCS1_S139,2970.0,375.0,1690.0,9187934.0,546.0,3.06,9.11,5.3508,2561929.0,78.69665132232473,4.788288,3.06,1.748627450980392
BCS1_S141,3060.0,960.0,2250.0,9377609.0,578.5,1.43,4.57,5.6693,1607124.0,37.89851593387761,2.910336,1.43,3.9645454545454544
BCS1_S144,2650.0,650.0,1980.0,6715148.0,502.5,1.54,4.77,4.9245,1940095.0,53.782993892689575,2.66112,1.54,3.1977272727272728
BCS1_S146,3770.0,605.0,2525.0,11410824.0,959.0,2.82,14.98,9.3982,3145344.0,80.73116066935084,5.27904,2.82,3.332695035460993
BCS1_S149,4650.0,1115.0,3235.0,14074359.0,738.5,3.02,12.73,7.237299999999999,2446693.0,63.13522508787288,5.624447999999999,3.02,2.396456953642384
BCS1_S151,5035.0,1215.0,3540.0,16189011.0,791.5,1.84,8.49,7.7566999999999995,2520118.0,63.647561839284116,3.497472,1.84,4.215597826086956
BCS1_S154,5950.0,1420.0,4125.0,18234240.0,619.0,1.43,5.07,6.066199999999999,2050783.0,52.91903091319338,2.663232,1.43,4.2420979020979015
BCS1_S156,4605.0,1000.0,3040.0,13810282.0,1619.5,2.39,20.62,15.8711,4769330.0,115.63936934522236,4.726464,2.39,6.640627615062761
BCS1_S159,6165.0,1100.0,3725.0,16518578.0,1679.5,2.41,21.6,16.4591,5083416.0,125.31940311849448,4.6966079999999994,2.41,6.829502074688796
BCS1_S161,885.0,295.0,610.0,3823297.0,323.5,5.7,32.6,3.1703,1166342.0,31.380645706093883,10.17792,5.7,0.5561929824561404
BCS1_S164,1225.0,435.0,945.0,4883393.0,198.5,6.79,19.15,1.9453,931397.0,28.610412614434907,10.624992,6.79,0.28649484536082476
BCS2_S1,8680.0,1915.0,6915.0,35320216.0,827.5,1.92,7.53,8.1095,4077891.0,128.4999778391215,2.930688,1.92,4.2236979166666675
BCS2_S4,10320.0,2530.0,7580.0,41993624.0,939.0,1.92,9.63,9.2022,4056583.0,119.30132068695946,3.13344,1.92,4.7928125
BCS2_S6,7695.0,1805.0,5225.0,29362712.0,1175.0,2.22,12.53,11.514999999999999,4331885.0,117.7364185729489,3.921408000000001,2.22,5.186936936936936
BCS2_S9,8755.0,2905.0,7910.0,31220808.0,1115.0,1.51,8.91,10.927,4157572.0,113.56591947514886,2.652768,1.51,7.236423841059603
BCS2_S11,10640.0,2535.0,7665.0,602332928.0,1107.5,2.08,9.92,10.8535,4275931.0,118.53664823115166,3.59424,2.08,5.218028846153846
BCS2_S14,9265.0,2420.0,6285.0,399497536.0,1075.0,2.05,11.03,10.535,4374336.0,125.20473157415833,3.444,2.05,5.139024390243903
BCS2_S16,8760.0,1755.0,5775.0,32295584.0,1160.0,2.85,18.53,11.368,5718903.0,180.13289944819448,4.35024,2.85,3.988771929824561
BCS2_S19,10635.0,2715.0,7580.0,43820892.0,1089.0,2.62,15.01,10.6722,4990393.0,151.3221385832851,4.15008,2.62,4.073358778625954
BCS2_S21,7370.0,1600.0,4855.0,27171056.0,1011.0,1.47,8.92,9.9078,4167826.0,119.79255669569224,2.455488,1.47,6.74
BCS2_S24,8435.0,1985.0,6120.0,28231772.0,1242.0,1.82,12.56,12.1716,4288683.0,113.02830536474929,3.3196799999999995,1.82,6.687692307692307
BCS2_S26,5335.0,1070.0,3485.0,29558462.0,759.0,2.53,10.3,7.4382,3797575.0,120.11491500594846,3.837503999999999,2.53,2.9400000000000004
BCS2_S29,5045.0,965.0,3580.0,26177010.0,767.5,1.72,7.31,7.5215,3202810.0,92.52657747053752,2.856576,1.72,4.37296511627907
BCS2_S31,9095.0,1960.0,6370.0,45974992.0,1198.5,3.57,21.62,11.7453,4627272.0,128.27645409032527,6.16896,3.57,3.29
BCS2_S34,10540.0,2540.0,7755.0,57106128.0,1191.0,3.56,21.25,11.6718,4846357.0,138.71519563239306,5.9808,3.56,3.2785955056179774
BCS2_S36,6635.0,1540.0,4645.0,24188520.0,933.5,3.67,20.0,9.148299999999999,4032823.0,118.60253765844159,5.98944,3.67,2.492724795640327
BCS2_S39,7185.0,1460.0,4735.0,27100300.0,885.0,3.94,20.41,8.673,3909408.0,116.50427156000404,6.354432,3.94,2.201269035532995
BCS2_S41,6205.0,1385.0,4020.0,20351260.0,736.0,3.06,10.28,7.2128,3295751.0,98.64039987840022,4.905792,3.06,2.357124183006536
BCS2_S44,8170.0,1985.0,5515.0,28211384.0,719.0,2.1,8.27,7.0462,3176118.0,94.65149293970951,3.3868799999999997,2.1,3.3553333333333333
BCS2_S46,8105.0,2105.0,5830.0,37669620.0,1081.5,2.6,15.64,10.5987,4910135.0,147.58039993936097,4.1433599999999995,2.6,4.076423076923076
BCS2_S49,9450.0,2490.0,6990.0,37671888.0,1148.5,2.6,15.61,11.2553,4961646.0,145.91860150050368,4.2432,2.6,4.328961538461538
BCS2_S51,7865.0,1870.0,5495.0,27448150.0,1058.5,3.02,15.63,10.3733,3694071.0,97.86600789020997,5.479488,3.02,3.434867549668874
BCS2_S54,7625.0,1360.0,5290.0,25520720.0,887.5,2.0,8.28,8.6975,3271956.0,88.9285714753125,3.5328,2.0,4.34875
BCS2_S56,6430.0,2170.0,4940.0,35625288.0,1020.5,2.12,12.02,10.0009,5380477.0,174.41236449500911,3.134208,2.12,4.717405660377358
BCS2_S59,7820.0,2260.0,5845.0,42842460.0,1057.5,2.3299999999999996,14.129999999999999,10.3635,5487054.0,177.2603917696684,3.4670399999999995,2.3299999999999996,4.447854077253219
BCS2_S61,6425.0,1585.0,4605.0,17849214.0,1352.0,1.21,8.99,13.2496,4017755.0,97.95836588313935,2.38128,1.21,10.950082644628099
BCS2_S64,6445.0,1820.0,4715.0,21794434.0,1484.0,1.58,13.11,14.543199999999999,5179028.0,137.20657128868362,2.8667519999999995,1.58,9.204556962025315
BCS2_S66,3965.0,1165.0,2790.0,13986823.0,580.5,1.0299999999999998,3.4,5.688899999999999,2391916.0,68.78296653001914,1.7205119999999996,1.0299999999999998,5.523203883495146
BCS2_S69,2105.0,860.0,1870.0,7118275.0,734.0,1.4200000000000004,5.68,7.1932,3024404.0,86.97105500953325,2.3719680000000007,1.4200000000000004,5.0656338028169
BCS2_S71,3730.0,410.0,2380.0,13751430.0,1208.5,1.7100000000000002,11.5,11.8433,4558206.0,125.12927090999676,2.987712,1.7100000000000002,6.925906432748537
BCS2_S74,3535.0,525.0,2240.0,14565760.0,1546.5,1.6600000000000001,13.870000000000001,15.1557,4972454.0,126.26345505851485,3.1393920000000004,1.6600000000000001,9.129939759036143
BCS2_S76,2615.0,415.0,1580.0,10096216.0,561.5,1.2399999999999998,3.94,5.5027,2117859.0,58.13825868097905,2.166528,1.2399999999999998,4.437661290322581
BCS2_S79,4865.0,1805.0,4745.0,22827440.0,750.0,1.4200000000000004,5.9399999999999995,7.35,3570382.0,110.11402635523937,2.2083840000000006,1.4200000000000004,5.176056338028167
BCS2_S82,185.0,40.0,75.0,788796.0,565.0,0.8399999999999999,2.78,5.537,2181400.0,60.47242099377037,1.4515199999999997,0.8399999999999999,6.591666666666668
BCS2_S85,365.0,310.0,345.0,1392773.0,590.5,2.29,4.08,5.7869,2353995.0,66.47012969299904,3.891168,2.29,2.5270305676855895
BCS2_S87,250.0,200.0,190.0,780784.0,1042.0,1.94,10.77,10.211599999999999,4293500.0,125.61914491765484,3.221952,1.94,5.263711340206185
BCS2_S90,150.0,55.0,55.0,468471.0,915.5,2.3200000000000003,9.99,8.9719,3955061.0,116.31561138329221,3.7862400000000007,2.3200000000000003,3.8671982758620684
BCS2_S92,295.0,215.0,295.0,1040634.0,469.5,0.8799999999999997,2.29,4.6011,1812686.0,46.28569984285485,1.5628799999999994,0.8799999999999997,5.228522727272729
BCS2_S95,290.0,60.0,210.0,1210182.0,496.5,1.0299999999999998,2.7,4.8656999999999995,2173661.0,64.20747070212003,1.6710719999999997,1.0299999999999998,4.723980582524272
BCS2_S97,1225.0,615.0,910.0,4883393.0,543.0,1.1200000000000003,3.38,5.3214,2071989.0,57.15977732572731,1.9461120000000007,1.1200000000000003,4.751249999999998
BCS2_S100,2320.0,1820.0,2170.0,9681459.0,353.5,0.8100000000000002,1.8799999999999997,3.4642999999999997,1392229.0,39.125133685916325,1.3841280000000005,0.8100000000000002,4.276913580246912
BCS2_S102,4195.0,3060.0,3945.0,15465751.0,792.5,1.8399999999999999,8.33,7.7665,3772704.0,116.35382118203627,2.861568,1.8399999999999999,4.220923913043478
BCS2_S105,5430.0,2040.0,4965.0,17632488.0,911.0,1.9299999999999997,9.43,8.9278,4024260.0,119.92699592221886,3.1127039999999995,1.9299999999999997,4.625803108808291
BCS2_S107,5570.0,2450.0,5125.0,21675810.0,798.5,1.8399999999999999,7.88,7.8252999999999995,3449608.0,101.45059059482122,3.0028799999999998,1.8399999999999999,4.252880434782608
BCS2_S110,5405.0,2030.0,5085.0,25361216.0,815.0,1.94,8.27,7.987,3474965.0,101.740929462713,3.184704,1.94,4.117010309278351
BCS2_S112,7690.0,1865.0,5525.0,38476092.0,1004.5,1.81,9.9,9.8441,4713292.0,144.78165980453332,2.8322879999999997,1.81,5.438729281767955
BCS2_S115,11670.0,3195.0,8755.0,64657404.0,1264.5,1.64,11.48,12.3921,4769427.0,130.92756563151917,2.865408,1.64,7.556158536585365
BCS2_S122,7805.0,1140.0,4960.0,37155776.0,493.5,1.28,2.36,4.8363,1991597.0,56.50352948970409,2.162688,1.28,3.7783593749999995
BCS2_S125,4435.0,3240.0,0.0,21319848.0,331.5,0.51,1.15,3.2487,1208515.0,32.680957397031705,0.90576,0.51,6.37
BCS2_S127,10725.0,2805.0,7705.0,41408000.0,1828.5,2.09,20.7,17.9193,6592448.0,177.37097580708704,3.731904,2.09,8.573827751196173
BCS2_S130,7290.0,2020.0,5560.0,27817308.0,1756.5,2.19,21.22,17.2137,6065275.0,159.85041736971183,3.99456,2.19,7.86013698630137
BCS2_S132,9050.0,2640.0,6640.0,32992632.0,1145.5,2.41,14.83,11.2259,4884138.0,142.9990609810279,3.9562559999999998,2.41,4.65804979253112
BCS2_S135,9295.0,2690.0,7180.0,30183050.0,775.5,1.75,7.66,7.5999,3553765.0,107.75970474870302,2.772,1.75,4.3427999999999995
BCS2_S137,7195.0,1635.0,4790.0,19988342.0,427.0,1.53,1.73,4.1846,1474451.0,38.85916778643151,2.79072,1.53,2.735032679738562
BCS2_S140,8795.0,2335.0,6680.0,23123188.0,531.5,1.24,3.52,5.208699999999999,1533010.0,36.867160297843895,2.476032,1.24,4.200564516129032
BCS2_S142,9005.0,2575.0,6910.0,45055552.0,865.5,2.23,11.05,8.4819,4330437.0,136.96898410757362,3.382464,2.23,3.803542600896861
BCS2_S145,9050.0,2915.0,7070.0,51598944.0,1465.0,2.86,20.58,14.357,5525670.0,151.68753155411275,4.996992,2.86,5.01993006993007
BCS2_S147,8900.0,2565.0,6305.0,30096272.0,644.0,3.22,9.36,6.3111999999999995,3222185.0,101.91568545959261,4.884096,3.22,1.9599999999999997
BCS2_S150,8750.0,2565.0,6195.0,27068828.0,653.0,4.0,16.15,6.3994,3766907.0,128.31800542335168,5.6448,4.0,1.59985
BCS2_S152,9535.0,2390.0,6920.0,28860002.0,368.5,0.78,1.64,3.6113,1487140.0,42.19159192898878,1.317888,0.78,4.629871794871795
BCS2_S155,7485.0,1350.0,5370.0,23155450.0,478.0,2.31,4.25,4.6844,2355567.0,74.22717753123877,3.5259840000000002,2.31,2.027878787878788
BCS2_S157,10680.0,3855.0,8410.0,49637452.0,1516.5,1.85,16.87,14.861699999999999,5855033.0,162.31225918062432,3.1968,1.85,8.033351351351351
BCS2_S160,9620.0,2560.0,6955.0,43675912.0,1323.0,1.99,14.04,12.965399999999999,4769926.0,128.3356855306405,3.553344,1.99,6.515276381909548
BCS2_S162,10895.0,3310.0,8310.0,40166712.0,1505.0,2.46,15.27,14.748999999999999,5198560.0,136.96264055873402,4.48704,2.46,5.9955284552845525
BCS2_S165,10820.0,3440.0,8260.0,42106332.0,1130.5,2.47,15.14,11.078899999999999,4820182.0,141.12652853692887,4.054752000000001,2.47,4.485384615384615
BCS3_S4,7940.0,1010.0,4940.0,24797708.0,1612.0,2.0,17.31,15.7976,5748480.0,153.8744951807665,3.5904,2.0,7.8988
BCS3_S9,2035.0,80.0,735.0,9239136.0,1327.0,1.58,11.12,13.0046,4309081.0,110.00923182219724,2.972928,1.58,8.230759493670886
BCS3_S14,10965.0,2375.0,8495.0,35605932.0,1504.0,1.54,12.39,14.7392,5033857.0,130.58771794001643,2.853312,1.54,9.57090909090909
BCS3_S19,7465.0,460.0,4325.0,24002178.0,1039.0,1.93,10.8,10.1822,4227846.0,121.01182893539583,3.2424,1.93,5.2757512953367875
BCS3_S24,5145.0,440.0,3460.0,17580214.0,1065.5,1.41,8.53,10.4419,4065753.0,112.16158884081484,2.450016,1.41,7.405602836879433
BCS3_S29,9445.0,2655.0,7080.0,37651956.0,1028.0,1.5,7.91,10.074399999999999,4183086.0,119.73066424021837,2.52,1.5,6.716266666666666
BCS3_S39,7340.0,1930.0,5470.0,28563814.0,1045.0,2.13,10.27,10.241,3809647.0,103.02141924554488,3.7828800000000005,2.13,4.807981220657277
BCS3_S44,2405.0,120.0,1040.0,9909661.0,691.0,1.34,5.1,6.7718,2920860.0,84.76550035773799,2.212608,1.34,5.053582089552238
BCS3_S54,9440.0,2260.0,6905.0,31922336.0,1167.5,1.82,10.08,11.4415,4403563.0,120.884090846025,3.179904,1.82,6.286538461538461
BCS3_S74,6675.0,1535.0,4775.0,20732708.0,1373.0,1.56,11.54,13.4554,4691474.0,0.25393536211370604,7.488,1.56,8.625256410256409
BCS3_S79,3200.0,355.0,2025.0,8717022.0,1057.0,1.7,8.86,10.3586,3466766.0,0.1954913894786506,24.48,1.7,6.0932941176470585
BCS3_S84,3735.0,520.0,2545.0,16499026.0,1651.0,2.76,25.36,16.1798,5414976.0,0.3053512620901156,66.24,2.76,5.862246376811595
BCS3_S89,3800.0,620.0,2575.0,12339493.0,2041.5,2.19,23.41,20.0067,5671466.0,0.04719674451521585,10.512,2.19,9.135479452054794
BCS3_S94,3780.0,660.0,2485.0,11441092.0,1302.0,3.93,38.94,12.759599999999999,4746564.0,0.030100495399858453,56.592,3.93,3.246717557251908
BCS3_S99,3635.0,535.0,2560.0,11803700.0,951.0,3.23,16.9,9.319799999999999,3428722.0,0.021985845718329792,77.52,3.23,2.8853869969040247
BCS3_S104,5855.0,1665.0,4355.0,22605488.0,1625.5,2.08,17.75,15.9299,5175555.0,0.3006350554376032,29.952,2.08,7.6586057692307685
BCS3_S109,7320.0,2005.0,5260.0,26103520.0,1202.0,1.72,10.72,11.7796,3827141.0,0.2223090351497995,24.768,1.72,6.848604651162791
BCS3_S114,6765.0,885.0,4570.0,28230632.0,1039.5,1.72,8.48,10.1871,4143908.0,117.0121927449153,2.9226240000000003,1.72,5.9227325581395345
BCS3_S119,6755.0,970.0,4865.0,21935072.0,532.5,1.24,3.62,5.2185,2498584.0,76.7508549984211,1.940352,1.24,4.2084677419354835
BCS3_S124,4475.0,320.0,2305.0,18438974.0,614.5,0.99,3.4,6.0221,2391344.0,66.87891481351726,1.701216,0.99,6.082929292929293
BCS3_S129,7995.0,1255.0,5600.0,27607100.0,1227.5,1.93,12.34,12.029499999999999,5188648.0,150.57836713331892,3.186816,1.93,6.232901554404145
BCS3_S134,7970.0,880.0,5065.0,36184720.0,679.5,0.99,5.97,6.6591,2251223.0,58.09124637401439,1.8437759999999999,0.99,6.726363636363636
BCS3_S139,2475.0,180.0,1170.0,9444147.0,719.0,0.92,3.84,7.0462,2456788.0,64.4102836821607,1.686912,0.92,7.65891304347826
BCS3_S144,3450.0,380.0,1680.0,12170123.0,1375.5,1.56,11.94,13.479899999999999,4700016.0,123.22162059083729,2.860416,1.56,8.640961538461537
BCS3_S149,5460.0,425.0,2740.0,19260544.0,678.0,0.99,3.57,6.6444,2617681.0,72.56690519252444,1.71072,0.99,6.711515151515152
BCS3_S161,7350.0,1015.0,4740.0,33369852.0,872.0,1.58,6.56,8.5456,3717999.0,108.85655275028924,2.593728,1.58,5.408607594936709
BCS4_S3,11490.0,2650.0,8480.0,49638064.0,1589.0,3.67,31.05,15.572199999999999,5109104.0,129.73335278886523,0.0,3.67,4.243106267029972
BCS4_S8,11595.0,2580.0,8785.0,41348400.0,1085.0,1.22,6.94,10.633,4189061.0,116.12845447476256,2.1081600000000003,1.22,8.715573770491803
BCS4_S13,11605.0,2890.0,8085.0,39653720.0,1093.5,2.29,12.99,10.7163,4359176.0,123.09074821218366,3.891168,2.29,4.679606986899564
BCS4_S18,4680.0,955.0,2850.0,19283664.0,1172.5,2.12,13.28,11.490499999999999,3627223.0,90.12620874880072,4.090751999999999,2.12,5.42004716981132
BCS4_S23,10580.0,3015.0,7125.0,33042788.0,602.0,0.94,3.14,5.8995999999999995,2659281.0,79.24923330974286,1.516032,0.94,6.276170212765957
BCS4_S33,11790.0,3895.0,8965.0,33708572.0,1794.0,4.1,36.29,17.5812,6194764.0,163.26310774908228,7.4784,4.1,4.28809756097561
BCS4_S38,9390.0,1815.0,6255.0,22963702.0,1230.0,1.11,7.73,12.054,3622276.0,87.8273691229537,2.1951360000000006,1.11,10.859459459459458
BCS4_S43,4505.0,1555.0,3485.0,16608631.0,777.5,1.43,5.29,7.6194999999999995,2932566.0,80.5031097497083,2.498496,1.43,5.328321678321678
BCS4_S48,10220.0,2365.0,7230.0,32540248.0,770.0,1.23,4.97,7.545999999999999,2972882.0,82.41374188531536,2.12544,1.23,6.134959349593496
BCS4_S53,3840.0,830.0,2280.0,14318455.0,545.5,1.54,4.5,5.345899999999999,2757488.0,87.98775178367353,2.321088,1.54,3.4713636363636358
BCS4_S113,9145.0,1815.0,6170.0,24043382.0,1178.5,1.69,10.61,11.549299999999999,3567018.0,87.93624089023264,3.2934719999999995,1.69,6.833905325443786
BCS4_S118,2030.0,500.0,1100.0,6725507.0,1288.0,2.47,17.9,12.622399999999999,3386318.0,77.60198056307941,5.169216000000001,2.47,5.110283400809716
BCS4_S123,5445.0,1780.0,5445.0,19417168.0,589.0,1.22,3.88,5.7722,2426940.0,69.79012452399874,2.037888,1.22,4.731311475409836
BCS4_S128,8905.0,2705.0,7145.0,27811534.0,1395.5,1.82,14.14,13.6759,4870171.0,129.02410393083423,3.3022080000000003,1.82,7.514230769230769
BCS4_S133,4035.0,1145.0,3075.0,13644770.0,1092.5,2.12,12.59,10.7065,3547604.0,90.56901715580292,3.9889919999999996,2.12,5.0502358490566035
BCS4_S138,4530.0,890.0,2795.0,17285652.0,188.0,0.75,0.86,1.8424,649173.0,17.108954435243852,1.368,0.75,2.4565333333333332
BCS4_S143,8045.0,1785.0,5245.0,27489372.0,1437.0,2.61,17.98,14.0826,3958471.0,92.82060207185226,5.3369279999999995,2.61,5.395632183908046
BCS4_S148,7160.0,3315.0,0.0,22361660.0,1140.0,1.93,11.91,11.171999999999999,3738990.0,95.96822019088629,3.6129599999999997,1.93,5.78860103626943
BCS4_S153,1235.0,240.0,725.0,3500351.0,510.0,1.02,2.71,4.998,1742645.0,45.687405671629975,1.8702719999999997,1.02,4.9
BCS4_S158,6440.0,2160.0,4330.0,18740304.0,1555.5,1.7,13.4,15.2439,4202271.0,97.69696198684265,3.5088,1.7,8.967
BCS4_S164,8025.0,1670.0,5625.0,25551418.0,950.5,1.2,6.37,9.3149,2567829.0,59.69846503921179,2.4768,1.2,7.762416666666667
PS-S2,1855.0,480.0,1295.0,6916860.0,672.0,2.14,7.77,6.5856,3079470.0,93.3778,3.38976,2.14,3.07738
PS-S5,3080.0,570.0,2070.0,13132400.0,753.0,1.61,6.69,7.3794,2572960.0,67.4561,2.9521,1.61,4.58348
PS-S7,1320.0,415.0,920.0,4866460.0,346.0,6.07,16.9,3.3908,1551600.0,46.3717,9.73142,6.07,0.558616
PS-S10,1645.0,445.0,1150.0,6557700.0,196.0,5.92,16.09,1.9208,1073800.0,35.5346,8.58163,5.92,0.324459
PS-S12,1835.0,435.0,1105.0,6921330.0,326.5,1.85,3.52,3.1997,1380120.0,40.052,3.05472,1.85,1.72957
PS-S15,2045.0,440.0,1370.0,7713310.0,422.5,1.66,3.87,4.1405,1575400.0,43.0328,2.91629,1.66,2.49428
PS-S17,1200.0,300.0,750.0,4326460.0,242.0,1.15,1.61,2.3716,872503.0,23.4749,2.05344,1.15,2.06226
PS-S20,1650.0,420.0,1120.0,5697530.0,209.0,2.86,1.68,2.0482,833167.0,23.5263,4.85971,2.86,0.716154
PS-S20,1650.0,420.0,1120.0,5697530.0,209.0,2.86,1.68,2.0482,833167.0,23.5263,4.85971,2.86,0.716154