File: etapa3/nans.csv
Primary ID,MW_Spartan,Energy,Solvation E,HOMO,Dipol,Tautomeri,LUMO,Conformeri,Area A^2,Volum A^3,Acc area A^2,Min ElPot kJ/mol,MinLocIonPot kJ/mol,LogP,PSA A^2,Ovality,MaxElPot kJ/mo,Polaririzability,ZPE kJ/mol,H0,Cv,S0,G0,ST-Diam (mm),3PBT-Diam (mm),3PBT-Radius (mm),ST-Hardness (g),ST-Rigidity at 2% deformation (g),ST-Rigidity at 4% deformation (g),ST-Peak stress (N/mp),3PBT-Hardness (g),3PBT-Deformation at hardness (mm),3PBT-Total work (mJ),3PBT-Maximum force (N),3PBT-Peak stress (N/mp),3PBT-Flexural stress (g/mmp) (Samaro 2021 Prasad 2019),3PBT-Flexural strain (%),3PBT-Breaking distance (mm),3PBT-Stiffness (N/mm) (Hu 2022)
BCS1_S1,408.88,-1722.98077,-51.76,-5.57,5.49,2.0,-1.16,15552.0,429.97,401.84,261.41,-221.01,31.75,0.15,78.001,1.63,185.59,72.93,1137.9,-1722.52309,311.44,653.51,-1722.5973,1.99,1.88,0.94,8075.0,1260.0,5550.0,25462604.0,1532.0,5.79,15.65,15.0136,5404240.0,143.91684868373792,10.449792,5.79,2.593022452504318
BCS1_S5,408.88,-1722.98077,-51.76,-5.57,5.49,2.0,-1.16,15552.0,429.97,401.84,261.41,-221.01,31.75,0.15,78.001,1.63,185.59,72.93,1137.9,-1722.52309,311.44,653.51,-1722.5973,1.9,1.83,0.915,9005.0,2480.0,6770.0,31094676.0,,,,,,,,,
BCS1_S9,408.88,-1722.98077,-51.76,-5.57,5.49,2.0,-1.16,15552.0,429.97,401.84,261.41,-221.01,31.75,0.15,78.001,1.63,185.59,72.93,1137.9,-1722.52309,311.44,653.51,-1722.5973,1.85,1.52,0.76,8680.0,2165.0,6120.0,31643764.0,707.5,2.03,7.68,6.9334999999999996,3833262.0,125.75408559398917,2.9621759999999995,2.03,3.4155172413793102
BCS1_S13,408.88,-1722.98077,-51.76,-5.57,5.49,2.0,-1.16,15552.0,429.97,401.84,261.41,-221.01,31.75,0.15,78.001,1.63,185.59,72.93,1137.9,-1722.52309,311.44,653.51,-1722.5973,1.88,1.97,0.985,7830.0,1760.0,5605.0,27620888.0,954.5,1.1,6.17,9.354099999999999,3068999.0,77.92982079104586,2.08032,1.1,8.503727272727271
BCS1_S17,408.88,-1722.98077,-51.76,-5.57,5.49,2.0,-1.16,15552.0,429.97,401.84,261.41,-221.01,31.75,0.15,78.001,1.63,185.59,72.93,1137.9,-1722.52309,311.44,653.51,-1722.5973,1.67,1.78,0.89,4705.0,1030.0,3375.0,21068624.0,822.0,1.77,8.28,8.0556,3237376.0,90.97838724136697,3.024576,1.77,4.5511864406779665
BCS1_S21,408.88,-1722.98077,-51.76,-5.57,5.49,2.0,-1.16,15552.0,429.97,401.84,261.41,-221.01,31.75,0.15,78.001,1.63,185.59,72.93,1137.9,-1722.52309,311.44,653.51,-1722.5973,1.87,1.81,0.905,4615.0,1095.0,3170.0,16457342.0,686.5,1.25,4.72,6.7277,2619558.0,72.2655380002059,2.172,1.25,5.38216
BCS1_S25,408.88,-1722.98077,-51.76,-5.57,5.49,2.0,-1.16,15552.0,429.97,401.84,261.41,-221.01,31.75,0.15,78.001,1.63,185.59,72.93,1137.9,-1722.52309,311.44,653.51,-1722.5973,1.92,1.82,0.91,4880.0,575.0,3315.0,16502225.0,788.5,2.24,9.46,7.7273,2974055.0,81.64206049857879,3.9137280000000008,2.24,3.4496874999999996
BCS1_S29,408.88,-1722.98077,-51.76,-5.57,5.49,2.0,-1.16,15552.0,429.97,401.84,261.41,-221.01,31.75,0.15,78.001,1.63,185.59,72.93,1137.9,-1722.52309,311.44,653.51,-1722.5973,1.89,1.76,0.88,7705.0,2670.0,6025.0,26889764.0,668.5,1.34,5.15,6.5512999999999995,2697838.0,76.54024207470556,2.264064,1.34,4.889029850746268
BCS1_S33,408.88,-1722.98077,-51.76,-5.57,5.49,2.0,-1.16,15552.0,429.97,401.84,261.41,-221.01,31.75,0.15,78.001,1.63,185.59,72.93,1137.9,-1722.52309,311.44,653.51,-1722.5973,1.77,1.64,0.82,9035.0,3060.0,6780.0,36017512.0,700.0,1.52,5.91,6.859999999999999,3253391.0,99.0587672750404,2.3930879999999997,1.52,4.513157894736842
BCS1_S37,408.88,-1722.98077,-51.76,-5.57,5.49,2.0,-1.16,15552.0,429.97,401.84,261.41,-221.01,31.75,0.15,78.001,1.63,185.59,72.93,1137.9,-1722.52309,311.44,653.51,-1722.5973,1.86,2.14,1.07,6635.0,1505.0,4575.0,23921736.0,1494.0,1.53,10.48,14.6412,4069760.0,95.15589550266193,3.1432320000000002,1.53,9.569411764705881
BCS1_S41,408.88,-1722.98077,-51.76,-5.57,5.49,2.0,-1.16,15552.0,429.97,401.84,261.41,-221.01,31.75,0.15,78.001,1.63,185.59,72.93,1137.9,-1722.52309,311.44,653.51,-1722.5973,1.96,1.93,0.965,5980.0,1600.0,5980.0,19418466.0,530.5,0.74,2.51,5.1989,1775573.0,46.06169173349649,1.3710719999999998,0.74,7.025540540540541
BCS1_S45,408.88,-1722.98077,-51.76,-5.57,5.49,2.0,-1.16,15552.0,429.97,401.84,261.41,-221.01,31.75,0.15,78.001,1.63,185.59,72.93,1137.9,-1722.52309,311.44,653.51,-1722.5973,1.88,1.91,0.955,7070.0,1725.0,5600.0,24939934.0,707.5,0.92,3.86,6.9334999999999996,2417493.0,63.38007747583961,1.686912,0.92,7.53641304347826
BCS1_S49,408.88,-1722.98077,-51.76,-5.57,5.49,2.0,-1.16,15552.0,429.97,401.84,261.41,-221.01,31.75,0.15,78.001,1.63,185.59,72.93,1137.9,-1722.52309,311.44,653.51,-1722.5973,1.95,1.74,0.87,3375.0,320.0,2120.0,11069379.0,405.0,1.04,2.66,3.969,1668779.0,47.98811618373428,1.737216,1.04,3.8163461538461534
BCS1_S53,408.88,-1722.98077,-51.76,-5.57,5.49,2.0,-1.16,15552.0,429.97,401.84,261.41,-221.01,31.75,0.15,78.001,1.63,185.59,72.93,1137.9,-1722.52309,311.44,653.51,-1722.5973,1.77,1.79,0.895,5190.0,1090.0,3625.0,20689640.0,797.0,1.83,8.04,7.8106,3101548.0,86.74124508767005,3.144672,1.83,4.2680874316939885
BCS1_S57,171.15,-623.872375,-43.28,-7.0,4.96,0.0,-2.57,18.0,182.61,158.8,132.37,-164.53,36.6,-0.67,61.273,1.29,147.61,53.21,432.31,-623.697068,128.7,403.58,-623.742899,2.16,2.04,1.02,6550.0,1180.0,4450.0,17818094.0,1794.5,1.42,14.07,17.5861,4835223.0,131.9409,2.780928,1.42,12.38458
BCS1_S61,171.15,-623.872375,-43.28,-7.0,4.96,0.0,-2.57,18.0,182.61,158.8,132.37,-164.53,36.6,-0.67,61.273,1.29,147.61,53.21,432.31,-623.697068,128.7,403.58,-623.742899,1.75,1.94,0.97,4935.0,825.0,3175.0,20081252.0,1730.5,5.94,23.1,16.9589,5733246.0,147.9425,11.06266,5.94,2.855034
BCS1_S65,171.15,-623.872375,-43.28,-7.0,4.96,0.0,-2.57,18.0,182.61,158.8,132.37,-164.53,36.6,-0.67,61.273,1.29,147.61,53.21,432.31,-623.697068,128.7,403.58,-623.742899,1.75,1.88,0.94,3330.0,240.0,1655.0,13550267.0,1158.5,5.81,11.88,11.3533,4086692.0,108.8301,10.48589,5.81,1.954096
BCS1_S69,171.15,-623.872375,-43.28,-7.0,4.96,0.0,-2.57,18.0,182.61,158.8,132.37,-164.53,36.6,-0.67,61.273,1.29,147.61,53.21,432.31,-623.697068,128.7,403.58,-623.742899,1.79,1.79,0.895,1750.0,240.0,950.0,6810174.0,266.5,1.36,2.15,2.6117,1037092.0,29.00444,2.337024,1.36,1.920368
BCS1_S73,171.15,-623.872375,-43.28,-7.0,4.96,0.0,-2.57,18.0,182.61,158.8,132.37,-164.53,36.6,-0.67,61.273,1.29,147.61,53.21,432.31,-623.697068,128.7,403.58,-623.742899,1.94,1.8,0.9,10040.0,2470.0,7285.0,33263096.0,1281.0,1.9,13.07,12.5538,4947725.0,137.1065,3.2832,1.9,6.607263
BCS1_S77,171.15,-623.872375,-43.28,-7.0,4.96,0.0,-2.57,18.0,182.61,158.8,132.37,-164.53,36.6,-0.67,61.273,1.29,147.61,53.21,432.31,-623.697068,128.7,403.58,-623.742899,1.79,1.79,0.895,6320.0,2400.0,4830.0,24594456.0,1225.0,5.43,116.0,12.005,4767122.0,133.3225,9.330912,5.43,2.210866
BCS1_S81,171.15,-623.872375,-43.28,-7.0,4.96,0.0,-2.57,18.0,182.61,158.8,132.37,-164.53,36.6,-0.67,61.273,1.29,147.61,53.21,432.31,-623.697068,128.7,403.58,-623.742899,1.91,1.67,0.835,3425.0,1005.0,2725.0,11703058.0,354.5,1.45,2.88,3.4741,1587423.0,47.5109,2.32464,1.45,2.395931
BCS1_S85,171.15,-623.872375,-43.28,-7.0,4.96,0.0,-2.57,18.0,182.61,158.8,132.37,-164.53,36.6,-0.67,61.273,1.29,147.61,53.21,432.31,-623.697068,128.7,403.58,-623.742899,1.79,1.83,0.915,1240.0,170.0,725.0,4825494.0,397.5,1.24,3.05,3.8955,1482184.0,40.4865,2.178432,1.24,3.141532
BCS1_S89,171.15,-623.872375,-43.28,-7.0,4.96,0.0,-2.57,18.0,182.61,158.8,132.37,-164.53,36.6,-0.67,61.273,1.29,147.61,53.21,432.31,-623.697068,128.7,403.58,-623.742899,1.95,1.95,0.975,5125.0,995.0,3250.0,16809056.0,1500.0,2.41,20.2,14.7,4919724.0,126.274,4.51152,2.41,6.099585
BCS1_S93,171.15,-623.872375,-43.28,-7.0,4.96,0.0,-2.57,18.0,182.61,158.8,132.37,-164.53,36.6,-0.67,61.273,1.29,147.61,53.21,432.31,-623.697068,128.7,403.58,-623.742899,2.14,2.15,1.075,1515.0,220.0,1055.0,4126965.0,1153.5,1.86,12.37,11.3043,3116245.0,72.44837,3.83904,1.86,6.077581
BCS1_S97,171.15,-623.872375,-43.28,-7.0,4.96,0.0,-2.57,18.0,182.61,158.8,132.37,-164.53,36.6,-0.67,61.273,1.29,147.61,53.21,432.31,-623.697068,128.7,403.58,-623.742899,2.2,1.85,0.925,1920.0,700.0,1440.0,4954939.0,573.0,1.33,4.31,5.6154,2088926.0,56.48926,2.36208,1.33,4.222105
BCS1_S101,171.15,-623.872375,-43.28,-7.0,4.96,0.0,-2.57,18.0,182.61,158.8,132.37,-164.53,36.6,-0.67,61.273,1.29,147.61,53.21,432.31,-623.697068,128.7,403.58,-623.742899,1.91,2.1,1.05,4500.0,725.0,2760.0,15376280.0,1032.5,1.51,8.59,10.1185,2926406.0,69.59188,3.04416,1.51,6.700993
BCS1_S105,171.15,-623.872375,-43.28,-7.0,4.96,0.0,-2.57,18.0,182.61,158.8,132.37,-164.53,36.6,-0.67,61.273,1.29,147.61,53.21,432.31,-623.697068,128.7,403.58,-623.742899,1.87,1.84,0.92,6205.0,1470.0,4585.0,22127368.0,1448.0,4.7,51.38,14.1904,5338357.0,145.0913,8.30208,4.7,3.019234
BCS1_S109,171.15,-623.872375,-43.28,-7.0,4.96,0.0,-2.57,18.0,182.61,158.8,132.37,-164.53,36.6,-0.67,61.273,1.29,147.61,53.21,432.31,-623.697068,128.7,403.58,-623.742899,1.74,1.86,0.93,4395.0,1135.0,3090.0,18109340.0,984.5,4.84,95.65,9.6481,3549503.0,95.49999,8.642304,4.84,1.993409
BCS1_S113,151.16,-515.479688,-48.76,-5.48,4.68,1.0,-0.07,4.0,180.35,157.88,141.46,-194.78,37.62,0.55,42.81,1.28,262.72,52.9,419.09,-515.310042,126.12,388.09,-515.354113,2.08,2.1,1.05,4570.0,860.0,3265.0,13181291.0,1617.5,5.97,138.61,15.8515,4584467.0,109.02166953122365,12.035520000000002,5.97,2.6551926298157453
BCS1_S117,151.16,-515.479688,-48.76,-5.48,4.68,1.0,-0.07,4.0,180.35,157.88,141.46,-194.78,37.62,0.55,42.81,1.28,262.72,52.9,419.09,-515.310042,126.12,388.09,-515.354113,2.07,2.21,1.105,2170.0,530.0,1615.0,6314668.0,1301.0,4.27,128.29,12.7498,4481975.0,75.23620806072289,9.059231999999998,4.27,2.9859016393442626
BCS1_S121,151.16,-515.479688,-48.76,-5.48,4.68,1.0,-0.07,4.0,180.35,157.88,141.46,-194.78,37.62,0.55,42.81,1.28,262.72,52.9,419.09,-515.310042,126.12,388.09,-515.354113,2.15,2.07,1.035,1365.0,440.0,1100.0,3687625.0,559.5,6.1,57.77,5.483099999999999,1628137.0,39.37453861025743,12.12192,6.1,0.8988688524590164
BCS1_S125,151.16,-515.479688,-48.76,-5.48,4.68,1.0,-0.07,4.0,180.35,157.88,141.46,-194.78,37.62,0.55,42.81,1.28,262.72,52.9,419.09,-515.310042,126.12,388.09,-515.354113,2.16,1.88,0.94,1950.0,825.0,1530.0,5224855.0,379.0,5.98,38.52,3.7142,1336950.0,35.603450163927334,10.792704,5.98,0.6211036789297658
BCS1_S129,151.16,-515.479688,-48.76,-5.48,4.68,1.0,-0.07,4.0,180.35,157.88,141.46,-194.78,37.62,0.55,42.81,1.28,262.72,52.9,419.09,-515.310042,126.12,388.09,-515.354113,2.09,1.86,0.93,7905.0,1140.0,5210.0,22601040.0,1318.5,3.21,22.64,12.9213,4972454.0,127.89916959346147,5.731776,3.21,4.025327102803739
BCS1_S133,151.16,-515.479688,-48.76,-5.48,4.68,1.0,-0.07,4.0,180.35,157.88,141.46,-194.78,37.62,0.55,42.81,1.28,262.72,52.9,419.09,-515.310042,126.12,388.09,-515.354113,1.94,1.94,0.97,5430.0,1180.0,3910.0,17989902.0,1215.0,2.91,19.65,11.907,4025365.0,103.87176503962839,5.4195839999999995,2.91,4.091752577319587
BCS1_S137,151.16,-515.479688,-48.76,-5.48,4.68,1.0,-0.07,4.0,180.35,157.88,141.46,-194.78,37.62,0.55,42.81,1.28,262.72,52.9,419.09,-515.310042,126.12,388.09,-515.354113,1.78,1.67,0.835,2375.0,235.0,1370.0,9353732.0,607.5,2.91,9.82,5.9535,2720338.0,81.41853658441322,4.665311999999999,2.91,2.0458762886597937
BCS1_S141,151.16,-515.479688,-48.76,-5.48,4.68,1.0,-0.07,4.0,180.35,157.88,141.46,-194.78,37.62,0.55,42.81,1.28,262.72,52.9,419.09,-515.310042,126.12,388.09,-515.354113,2.02,2.12,1.06,3060.0,960.0,2250.0,9377609.0,578.5,1.43,4.57,5.6693,1607124.0,37.89851593387761,2.910336,1.43,3.9645454545454544
BCS1_S145,151.16,-515.479688,-48.76,-5.48,4.68,1.0,-0.07,4.0,180.35,157.88,141.46,-194.78,37.62,0.55,42.81,1.28,262.72,52.9,419.09,-515.310042,126.12,388.09,-515.354113,2.11,1.88,0.94,3660.0,1330.0,3010.0,10254954.0,898.5,4.56,88.76,8.805299999999999,3169523.0,84.40554082398074,8.229887999999997,4.56,1.9309868421052632
BCS1_S149,151.16,-515.479688,-48.76,-5.48,4.68,1.0,-0.07,4.0,180.35,157.88,141.46,-194.78,37.62,0.55,42.81,1.28,262.72,52.9,419.09,-515.310042,126.12,388.09,-515.354113,2.03,1.94,0.97,4650.0,1115.0,3235.0,14074359.0,738.5,3.02,12.73,7.237299999999999,2446693.0,63.13522508787288,5.624447999999999,3.02,2.396456953642384
BCS1_S153,151.16,-515.479688,-48.76,-5.48,4.68,1.0,-0.07,4.0,180.35,157.88,141.46,-194.78,37.62,0.55,42.81,1.28,262.72,52.9,419.09,-515.310042,126.12,388.09,-515.354113,1.96,1.95,0.975,5350.0,1200.0,3825.0,17372708.0,650.0,1.63,6.42,6.37,2131880.0,54.718722038663245,3.0513599999999994,1.63,3.9079754601227
BCS1_S157,151.16,-515.479688,-48.76,-5.48,4.68,1.0,-0.07,4.0,180.35,157.88,141.46,-194.78,37.62,0.55,42.81,1.28,262.72,52.9,419.09,-515.310042,126.12,388.09,-515.354113,2.19,2.08,1.04,6525.0,1225.0,4640.0,16973048.0,1434.0,2.15,17.62,14.0532,4136099.0,99.46850022033519,4.29312,2.15,6.536372093023256
BCS1_S161,151.16,-515.479688,-48.76,-5.48,4.68,1.0,-0.07,4.0,180.35,157.88,141.46,-194.78,37.62,0.55,42.81,1.28,262.72,52.9,419.09,-515.310042,126.12,388.09,-515.354113,1.7,1.86,0.93,885.0,295.0,610.0,3823297.0,323.5,5.7,32.6,3.1703,1166342.0,31.380645706093883,10.17792,5.7,0.5561929824561404
BCS1_S165,151.16,-515.479688,-48.76,-5.48,4.68,1.0,-0.07,4.0,180.35,157.88,141.46,-194.78,37.62,0.55,42.81,1.28,262.72,52.9,419.09,-515.310042,126.12,388.09,-515.354113,1.76,1.8,0.9,1020.0,370.0,805.0,4116372.0,250.5,6.43,26.32,2.4549,967152.0,26.811223821131815,11.111040000000001,6.43,0.38178849144634525
BCS2_S4,384.25,-1973.40635,-43.88,-5.66,8.92,2.0,-1.41,96.0,382.36,359.07,247.7,-228.79,36.47,2.1,45.544,1.57,258.04,69.5,902.57,-1973.04082,272.88,608.97,-1973.10997,1.8,1.7,0.85,10320.0,2530.0,7580.0,41993624.0,939.0,1.92,9.63,9.2022,4056583.0,119.30132068695946,3.13344,1.92,4.7928125
BCS2_S8,384.25,-1973.40635,-43.88,-5.66,8.92,2.0,-1.41,96.0,382.36,359.07,247.7,-228.79,36.47,2.1,45.544,1.57,258.04,69.5,902.57,-1973.04082,272.88,608.97,-1973.10997,1.8,1.86,0.93,10005.0,2250.0,7505.0,38628164.0,1174.0,1.63,10.36,11.5052,4234526.0,113.8821578329342,2.910528,1.63,7.0584049079754605
BCS2_S12,384.25,-1973.40635,-43.88,-5.66,8.92,2.0,-1.41,96.0,382.36,359.07,247.7,-228.79,36.47,2.1,45.544,1.57,258.04,69.5,902.57,-1973.04082,272.88,608.97,-1973.10997,1.82,1.8,0.9,10905.0,2035.0,8185.0,790411584.0,1110.5,2.36,10.67,10.8829,4287514.0,118.85774073200352,4.07808,2.36,4.611398305084745
BCS2_S16,384.25,-1973.40635,-43.88,-5.66,8.92,2.0,-1.41,96.0,382.36,359.07,247.7,-228.79,36.47,2.1,45.544,1.57,258.04,69.5,902.57,-1973.04082,272.88,608.97,-1973.10997,1.84,1.59,0.795,8760.0,1755.0,5775.0,32295584.0,1160.0,2.85,18.53,11.368,5718903.0,180.13289944819448,4.35024,2.85,3.988771929824561
BCS2_S20,384.25,-1973.40635,-43.88,-5.66,8.92,2.0,-1.41,96.0,382.36,359.07,247.7,-228.79,36.47,2.1,45.544,1.57,258.04,69.5,902.57,-1973.04082,272.88,608.97,-1973.10997,2.01,1.55,0.775,5820.0,1355.0,4030.0,18004638.0,1149.0,3.44,19.11,11.2602,5961821.0,192.59781573839146,5.118720000000001,3.44,3.2733139534883717
BCS2_S24,384.25,-1973.40635,-43.88,-5.66,8.92,2.0,-1.41,96.0,382.36,359.07,247.7,-228.79,36.47,2.1,45.544,1.57,258.04,69.5,902.57,-1973.04082,272.88,608.97,-1973.10997,1.93,1.9,0.95,8435.0,1985.0,6120.0,28231772.0,1242.0,1.82,12.56,12.1716,4288683.0,113.02830536474929,3.3196799999999995,1.82,6.687692307692307
BCS2_S28,384.25,-1973.40635,-43.88,-5.66,8.92,2.0,-1.41,96.0,382.36,359.07,247.7,-228.79,36.47,2.1,45.544,1.57,258.04,69.5,902.57,-1973.04082,272.88,608.97,-1973.10997,1.93,1.64,0.82,8585.0,2010.0,6240.0,37584864.0,842.0,2.02,9.67,8.2516,3913365.0,119.15354577940573,3.1802879999999996,2.02,4.084950495049505
BCS2_S32,384.25,-1973.40635,-43.88,-5.66,8.92,2.0,-1.41,96.0,382.36,359.07,247.7,-228.79,36.47,2.1,45.544,1.57,258.04,69.5,902.57,-1973.04082,272.88,608.97,-1973.10997,1.55,1.75,0.875,7770.0,1590.0,5215.0,40316228.0,1056.5,3.05,16.61,10.3537,4299056.0,123.05004549590535,5.124,3.05,3.3946557377049182
BCS2_S36,384.25,-1973.40635,-43.88,-5.66,8.92,2.0,-1.41,96.0,382.36,359.07,247.7,-228.79,36.47,2.1,45.544,1.57,258.04,69.5,902.57,-1973.04082,272.88,608.97,-1973.10997,1.85,1.7,0.85,6635.0,1540.0,4645.0,24188520.0,933.5,3.67,20.0,9.148299999999999,4032823.0,118.60253765844159,5.98944,3.67,2.492724795640327
BCS2_S40,384.25,-1973.40635,-43.88,-5.66,8.92,2.0,-1.41,96.0,382.36,359.07,247.7,-228.79,36.47,2.1,45.544,1.57,258.04,69.5,902.57,-1973.04082,272.88,608.97,-1973.10997,1.86,1.64,0.82,6000.0,1060.0,3770.0,21632316.0,774.0,3.03,13.03,7.5851999999999995,3597321.0,109.53069410125894,4.770432,3.03,2.5033663366336634
BCS2_S44,384.25,-1973.40635,-43.88,-5.66,8.92,2.0,-1.41,96.0,382.36,359.07,247.7,-228.79,36.47,2.1,45.544,1.57,258.04,69.5,902.57,-1973.04082,272.88,608.97,-1973.10997,1.9,1.68,0.84,8170.0,1985.0,5515.0,28211384.0,719.0,2.1,8.27,7.0462,3176118.0,94.65149293970951,3.3868799999999997,2.1,3.3553333333333333
BCS2_S48,384.25,-1973.40635,-43.88,-5.66,8.92,2.0,-1.41,96.0,382.36,359.07,247.7,-228.79,36.47,2.1,45.544,1.57,258.04,69.5,902.57,-1973.04082,272.88,608.97,-1973.10997,1.66,1.81,0.905,6955.0,1685.0,4795.0,31576504.0,1362.5,2.19,17.7,13.3525,5199051.0,143.42577643886457,3.8053440000000003,2.19,6.09703196347032
BCS2_S52,384.25,-1973.40635,-43.88,-5.66,8.92,2.0,-1.41,96.0,382.36,359.07,247.7,-228.79,36.47,2.1,45.544,1.57,258.04,69.5,902.57,-1973.04082,272.88,608.97,-1973.10997,1.82,1.8,0.9,8185.0,1715.0,5805.0,32235916.0,1224.0,2.43,15.27,11.995199999999999,4725724.0,131.00574034756625,4.19904,2.43,4.9362962962962955
BCS2_S56,418.57,-1351.67024,-37.56,-5.95,5.41,0.0,-0.56,17496.0,475.0,456.1,255.94,-215.71,35.83,4.56,59.244,1.66,253.46,77.1,1576.41,-1351.04329,360.53,679.55,-1351.12046,1.5,1.54,0.77,6430.0,2170.0,4940.0,35625288.0,1020.5,2.12,12.02,10.0009,5380477.0,174.41236449500911,3.134208,2.12,4.717405660377358
BCS2_S60,418.57,-1351.67024,-37.56,-5.95,5.41,0.0,-0.56,17496.0,475.0,456.1,255.94,-215.71,35.83,4.56,59.244,1.66,253.46,77.1,1576.41,-1351.04329,360.53,679.55,-1351.12046,1.58,1.71,0.855,8200.0,2210.0,6265.0,41027820.0,1277.0,1.9,13.35,12.5146,5444823.0,159.41492874096258,3.1190399999999996,1.9,6.586631578947369
BCS2_S64,418.57,-1351.67024,-37.56,-5.95,5.41,0.0,-0.56,17496.0,475.0,456.1,255.94,-215.71,35.83,4.56,59.244,1.66,253.46,77.1,1576.41,-1351.04329,360.53,679.55,-1351.12046,1.92,1.89,0.945,6445.0,1820.0,4715.0,21794434.0,1484.0,1.58,13.11,14.543199999999999,5179028.0,137.20657128868362,2.8667519999999995,1.58,9.204556962025315
BCS2_S68,418.57,-1351.67024,-37.56,-5.95,5.41,0.0,-0.56,17496.0,475.0,456.1,255.94,-215.71,35.83,4.56,59.244,1.66,253.46,77.1,1576.41,-1351.04329,360.53,679.55,-1351.12046,1.82,1.74,0.87,3660.0,540.0,2430.0,13804746.0,547.0,1.1299999999999997,3.62,5.3606,2253881.0,64.81357914198185,1.8875519999999992,1.1299999999999997,4.743893805309736
BCS2_S72,418.57,-1351.67024,-37.56,-5.95,5.41,0.0,-0.56,17496.0,475.0,456.1,255.94,-215.71,35.83,4.56,59.244,1.66,253.46,77.1,1576.41,-1351.04329,360.53,679.55,-1351.12046,1.83,1.71,0.855,4380.0,630.0,2560.0,16331987.0,779.0,1.2299999999999998,5.62,7.6342,3321470.0,97.24685159687536,2.0191679999999996,1.2299999999999998,6.206666666666668
BCS2_S76,418.57,-1351.67024,-37.56,-5.95,5.41,0.0,-0.56,17496.0,475.0,456.1,255.94,-215.71,35.83,4.56,59.244,1.66,253.46,77.1,1576.41,-1351.04329,360.53,679.55,-1351.12046,1.8,1.82,0.91,2615.0,415.0,1580.0,10096216.0,561.5,1.2399999999999998,3.94,5.5027,2117859.0,58.13825868097905,2.166528,1.2399999999999998,4.437661290322581
BCS2_S80,418.57,-1351.67024,-37.56,-5.95,5.41,0.0,-0.56,17496.0,475.0,456.1,255.94,-215.71,35.83,4.56,59.244,1.66,253.46,77.1,1576.41,-1351.04329,360.53,679.55,-1351.12046,1.78,,,740.0,705.0,575.0,2914426.0,,,,,,,,,
BCS2_S84,418.57,-1351.67024,-37.56,-5.95,5.41,0.0,-0.56,17496.0,475.0,456.1,255.94,-215.71,35.83,4.56,59.244,1.66,253.46,77.1,1576.41,-1351.04329,360.53,679.55,-1351.12046,1.77,1.88,0.94,85.0,55.0,55.0,338848.0,835.5,2.8,6.14,8.187899999999999,2947286.0,78.48728921361817,5.053439999999999,2.8,2.92425
BCS2_S88,418.57,-1351.67024,-37.56,-5.95,5.41,0.0,-0.56,17496.0,475.0,456.1,255.94,-215.71,35.83,4.56,59.244,1.66,253.46,77.1,1576.41,-1351.04329,360.53,679.55,-1351.12046,1.99,1.83,0.915,625.0,610.0,495.0,1970790.0,889.5,1.2700000000000002,6.5,8.7171,3316736.0,90.59810347367257,2.2311360000000002,1.2700000000000002,6.863858267716535
BCS2_S92,418.57,-1351.67024,-37.56,-5.95,5.41,0.0,-0.56,17496.0,475.0,456.1,255.94,-215.71,35.83,4.56,59.244,1.66,253.46,77.1,1576.41,-1351.04329,360.53,679.55,-1351.12046,1.88,1.85,0.925,295.0,215.0,295.0,1040634.0,469.5,0.8799999999999997,2.29,4.6011,1812686.0,46.28569984285485,1.5628799999999994,0.8799999999999997,5.228522727272729
BCS2_S96,418.57,-1351.67024,-37.56,-5.95,5.41,0.0,-0.56,17496.0,475.0,456.1,255.94,-215.71,35.83,4.56,59.244,1.66,253.46,77.1,1576.41,-1351.04329,360.53,679.55,-1351.12046,1.69,1.69,0.845,920.0,665.0,850.0,4027731.0,299.0,0.85,1.5299999999999998,2.9301999999999997,1309013.0,38.666734622223345,1.37904,0.85,3.4472941176470586
BCS2_S100,418.57,-1351.67024,-37.56,-5.95,5.41,0.0,-0.56,17496.0,475.0,456.1,255.94,-215.71,35.83,4.56,59.244,1.66,253.46,77.1,1576.41,-1351.04329,360.53,679.55,-1351.12046,1.73,1.78,0.89,2320.0,1820.0,2170.0,9681459.0,353.5,0.8100000000000002,1.8799999999999997,3.4642999999999997,1392229.0,39.125133685916325,1.3841280000000005,0.8100000000000002,4.276913580246912
BCS2_S104,418.57,-1351.67024,-37.56,-5.95,5.41,0.0,-0.56,17496.0,475.0,456.1,255.94,-215.71,35.83,4.56,59.244,1.66,253.46,77.1,1576.41,-1351.04329,360.53,679.55,-1351.12046,2.0,1.62,0.81,4785.0,2045.0,4265.0,14944210.0,726.0,1.8,7.11,7.1148,3456130.0,106.59037751187172,2.79936,1.8,3.9526666666666666
BCS2_S108,418.57,-1351.67024,-37.56,-5.95,5.41,0.0,-0.56,17496.0,475.0,456.1,255.94,-215.71,35.83,4.56,59.244,1.66,253.46,77.1,1576.41,-1351.04329,360.53,679.55,-1351.12046,1.72,1.65,0.825,5205.0,2245.0,5205.0,22001556.0,911.0,2.13,10.31,8.9278,4174700.0,126.58812511420818,3.3739199999999996,2.13,4.191455399061033
BCS2_S112,406.47,-1340.57487,-45.89,-5.43,3.61,0.0,-0.63,104976.0,450.1,425.31,304.91,-171.89,32.16,3.87,60.237,1.65,231.91,74.74,1220.82,-1340.08682,322.5,630.03,-1340.15836,1.58,1.63,0.815,7690.0,1865.0,5525.0,38476092.0,1004.5,1.81,9.9,9.8441,4713292.0,144.78165980453332,2.8322879999999997,1.81,5.438729281767955
BCS2_S116,406.47,-1340.57487,-45.89,-5.43,3.61,0.0,-0.63,104976.0,450.1,425.31,304.91,-171.89,32.16,3.87,60.237,1.65,231.91,74.74,1220.82,-1340.08682,322.5,630.03,-1340.15836,1.79,1.73,0.865,7660.0,1895.0,5760.0,29809104.0,883.5,1.94,,8.6583,3686883.0,106.51105041722464,3.221952,1.94,4.463041237113402
BCS2_S120,406.47,-1340.57487,-45.89,-5.43,3.61,0.0,-0.63,104976.0,450.1,425.31,304.91,-171.89,32.16,3.87,60.237,1.65,231.91,74.74,1220.82,-1340.08682,322.5,630.03,-1340.15836,1.75,,,8655.0,1280.0,5300.0,36117684.0,,,,,,,,,
BCS2_S124,406.47,-1340.57487,-45.89,-5.43,3.61,0.0,-0.63,104976.0,450.1,425.31,304.91,-171.89,32.16,3.87,60.237,1.65,231.91,74.74,1220.82,-1340.08682,322.5,630.03,-1340.15836,1.67,1.83,0.915,7540.0,1820.0,6250.0,33763536.0,364.5,0.7,1.62,3.5721,1359135.0,37.12536111990292,1.22976,0.7,5.103
BCS2_S128,406.47,-1340.57487,-45.89,-5.43,3.61,0.0,-0.63,104976.0,450.1,425.31,304.91,-171.89,32.16,3.87,60.237,1.65,231.91,74.74,1220.82,-1340.08682,322.5,630.03,-1340.15836,1.82,1.87,0.935,10370.0,3150.0,7775.0,39113448.0,1976.5,2.28,24.86,19.369699999999998,7048307.0,188.66807675234801,4.093056,2.28,8.495482456140351
BCS2_S132,406.47,-1340.57487,-45.89,-5.43,3.61,0.0,-0.63,104976.0,450.1,425.31,304.91,-171.89,32.16,3.87,60.237,1.65,231.91,74.74,1220.82,-1340.08682,322.5,630.03,-1340.15836,1.85,1.71,0.855,9050.0,2640.0,6640.0,32992632.0,1145.5,2.41,14.83,11.2259,4884138.0,142.9990609810279,3.9562559999999998,2.41,4.65804979253112
BCS2_S136,406.47,-1340.57487,-45.89,-5.43,3.61,0.0,-0.63,104976.0,450.1,425.31,304.91,-171.89,32.16,3.87,60.237,1.65,231.91,74.74,1220.82,-1340.08682,322.5,630.03,-1340.15836,2.15,2.15,1.075,8290.0,2285.0,6740.0,22395904.0,371.0,1.14,1.77,3.6357999999999997,1002277.0,23.301557632348842,2.3529599999999995,1.14,3.1892982456140353
BCS2_S140,406.47,-1340.57487,-45.89,-5.43,3.61,0.0,-0.63,104976.0,450.1,425.31,304.91,-171.89,32.16,3.87,60.237,1.65,231.91,74.74,1220.82,-1340.08682,322.5,630.03,-1340.15836,2.18,2.08,1.04,8795.0,2335.0,6680.0,23123188.0,531.5,1.24,3.52,5.208699999999999,1533010.0,36.867160297843895,2.476032,1.24,4.200564516129032
BCS2_S144,406.47,-1340.57487,-45.89,-5.43,3.61,0.0,-0.63,104976.0,450.1,425.31,304.91,-171.89,32.16,3.87,60.237,1.65,231.91,74.74,1220.82,-1340.08682,322.5,630.03,-1340.15836,1.59,1.59,0.795,9195.0,2845.0,7130.0,45312636.0,808.0,2.63,12.57,7.9184,3981796.0,125.47188168460444,4.014432,2.63,3.0107984790874527
BCS2_S148,406.47,-1340.57487,-45.89,-5.43,3.61,0.0,-0.63,104976.0,450.1,425.31,304.91,-171.89,32.16,3.87,60.237,1.65,231.91,74.74,1220.82,-1340.08682,322.5,630.03,-1340.15836,1.79,1.61,0.805,10160.0,3750.0,7640.0,39537920.0,798.0,3.19,13.33,7.820399999999999,3836131.0,119.35804219306789,4.930464,3.19,2.4515360501567396
BCS2_S152,406.47,-1340.57487,-45.89,-5.43,3.61,0.0,-0.63,104976.0,450.1,425.31,304.91,-171.89,32.16,3.87,60.237,1.65,231.91,74.74,1220.82,-1340.08682,322.5,630.03,-1340.15836,2.03,1.76,0.88,9535.0,2390.0,6920.0,28860002.0,368.5,0.78,1.64,3.6113,1487140.0,42.19159192898878,1.317888,0.78,4.629871794871795
BCS2_S156,406.47,-1340.57487,-45.89,-5.43,3.61,0.0,-0.63,104976.0,450.1,425.31,304.91,-171.89,32.16,3.87,60.237,1.65,231.91,74.74,1220.82,-1340.08682,322.5,630.03,-1340.15836,1.81,1.93,0.965,8660.0,1755.0,6005.0,33044976.0,1387.0,1.66,13.83,13.5926,4642261.0,120.4289659460125,3.075648,1.66,8.188313253012048
BCS2_S160,406.47,-1340.57487,-45.89,-5.43,3.61,0.0,-0.63,104976.0,450.1,425.31,304.91,-171.89,32.16,3.87,60.237,1.65,231.91,74.74,1220.82,-1340.08682,322.5,630.03,-1340.15836,1.66,1.86,0.93,9620.0,2560.0,6955.0,43675912.0,1323.0,1.99,14.04,12.965399999999999,4769926.0,128.3356855306405,3.553344,1.99,6.515276381909548
BCS2_S164,406.47,-1340.57487,-45.89,-5.43,3.61,0.0,-0.63,104976.0,450.1,425.31,304.91,-171.89,32.16,3.87,60.237,1.65,231.91,74.74,1220.82,-1340.08682,322.5,630.03,-1340.15836,1.91,1.95,0.975,11910.0,3940.0,9010.0,40695888.0,1393.5,2.0,12.62,13.6563,4570424.0,117.30852178596496,3.744,2.0,6.82815
BCS3_S3,225.2,-810.872343,-145.97,-5.85,11.56,5.0,-0.15,162.0,263.12,204.47,165.12,-280.68,33.04,-0.61,93.292,1.41,277.3,56.61,553.99,-810.647631,169.84,461.83,-810.700076,1.92,1.99,0.995,7210.0,1260.0,5330.0,24381360.0,1573.0,1.63,13.23,15.4154,4960084.0,124.59365226741876,3.113952,1.63,9.457300613496933
BCS3_S7,225.2,-810.872343,-145.97,-5.85,11.56,5.0,-0.15,162.0,263.12,204.47,165.12,-280.68,33.04,-0.61,93.292,1.41,277.3,56.61,553.99,-810.647631,169.84,461.83,-810.700076,1.81,1.84,0.92,7640.0,1195.0,5430.0,29152844.0,1016.0,1.43,8.35,9.9568,3745698.0,101.80442661286477,2.525952,1.43,6.962797202797202
BCS3_S11,225.2,-810.872343,-145.97,-5.85,11.56,5.0,-0.15,162.0,263.12,204.47,165.12,-280.68,33.04,-0.61,93.292,1.41,277.3,56.61,553.99,-810.647631,169.84,461.83,-810.700076,2.0,2.2,1.1,5405.0,880.0,3530.0,16880556.0,1474.0,1.13,8.5,14.4452,3803948.0,86.408380270569,2.38656,1.13,12.783362831858408
BCS3_S15,225.2,-810.872343,-145.97,-5.85,11.56,5.0,-0.15,162.0,263.12,204.47,165.12,-280.68,33.04,-0.61,93.292,1.41,277.3,56.61,553.99,-810.647631,169.84,461.83,-810.700076,2.08,1.94,0.97,5970.0,1370.0,4240.0,17219324.0,1394.0,1.39,10.5,13.6612,4618402.0,119.1746835104872,2.5887359999999995,1.39,9.828201438848922
BCS3_S19,225.2,-810.872343,-145.97,-5.85,11.56,5.0,-0.15,162.0,263.12,204.47,165.12,-280.68,33.04,-0.61,93.292,1.41,277.3,56.61,553.99,-810.647631,169.84,461.83,-810.700076,1.97,1.75,0.875,7465.0,460.0,4325.0,24002178.0,1039.0,1.93,10.8,10.1822,4227846.0,121.01182893539583,3.2424,1.93,5.2757512953367875
BCS3_S23,225.2,-810.872343,-145.97,-5.85,11.56,5.0,-0.15,162.0,263.12,204.47,165.12,-280.68,33.04,-0.61,93.292,1.41,277.3,56.61,553.99,-810.647631,169.84,461.83,-810.700076,1.88,1.9,0.95,5280.0,435.0,2605.0,18625580.0,1053.5,1.41,8.08,10.3243,3637784.0,95.87384839111381,2.57184,1.41,7.322198581560284
BCS3_S27,225.2,-810.872343,-145.97,-5.85,11.56,5.0,-0.15,162.0,263.12,204.47,165.12,-280.68,33.04,-0.61,93.292,1.41,277.3,56.61,553.99,-810.647631,169.84,461.83,-810.700076,1.74,1.75,0.875,7915.0,1645.0,5310.0,32613292.0,1060.5,1.59,9.04,10.3929,4315333.0,123.51592356687898,2.6712,1.59,6.536415094339622
BCS3_S31,225.2,-810.872343,-145.97,-5.85,11.56,5.0,-0.15,162.0,263.12,204.47,165.12,-280.68,33.04,-0.61,93.292,1.41,277.3,56.61,553.99,-810.647631,169.84,461.83,-810.700076,,,0.0,,,,,,,,,,,,,
BCS3_S35,225.2,-810.872343,-145.97,-5.85,11.56,5.0,-0.15,162.0,263.12,204.47,165.12,-280.68,33.04,-0.61,93.292,1.41,277.3,56.61,553.99,-810.647631,169.84,461.83,-810.700076,,,0.0,,,,,,,,,,,,,
BCS3_S39,225.2,-810.872343,-145.97,-5.85,11.56,5.0,-0.15,162.0,263.12,204.47,165.12,-280.68,33.04,-0.61,93.292,1.41,277.3,56.61,553.99,-810.647631,169.84,461.83,-810.700076,1.79,1.85,0.925,7340.0,1930.0,5470.0,28563814.0,1045.0,2.13,10.27,10.241,3809647.0,103.02141924554488,3.7828800000000005,2.13,4.807981220657277
BCS3_S43,225.2,-810.872343,-145.97,-5.85,11.56,5.0,-0.15,162.0,263.12,204.47,165.12,-280.68,33.04,-0.61,93.292,1.41,277.3,56.61,553.99,-810.647631,169.84,461.83,-810.700076,1.42,1.8,0.9,4765.0,455.0,2610.0,29575120.0,876.5,1.19,5.63,8.5897,3384066.0,93.81252566555705,2.05632,1.19,7.2182352941176475
BCS3_S47,225.2,-810.872343,-145.97,-5.85,11.56,5.0,-0.15,162.0,263.12,204.47,165.12,-280.68,33.04,-0.61,93.292,1.41,277.3,56.61,553.99,-810.647631,169.84,461.83,-810.700076,,,0.0,,,,,,,,,,,,,
BCS3_S51,225.2,-810.872343,-145.97,-5.85,11.56,5.0,-0.15,162.0,263.12,204.47,165.12,-280.68,33.04,-0.61,93.292,1.41,277.3,56.61,553.99,-810.647631,169.84,461.83,-810.700076,1.87,1.92,0.96,9420.0,2165.0,6640.0,33592232.0,1554.5,4.55,14.67,15.2341,5256703.0,137.0924265493225,8.38656,4.55,3.348153846153846
BCS3_S55,225.2,-810.872343,-145.97,-5.85,11.56,5.0,-0.15,162.0,263.12,204.47,165.12,-280.68,33.04,-0.61,93.292,1.41,277.3,56.61,553.99,-810.647631,169.84,461.83,-810.700076,1.84,1.93,0.965,9460.0,2515.0,7055.0,34876280.0,1329.0,2.61,10.61,13.0242,4448136.0,115.39300341907038,4.835808,2.61,4.990114942528736
BCS3_S59,266.34,-881.900569,-40.77,-6.0,4.32,1.0,-0.26,8748.0,325.48,288.66,198.44,-212.86,35.72,0.5,75.29,1.54,240.49,63.43,924.64,-881.530458,231.59,536.21,-881.59135,2.04,1.77,0.885,2525.0,375.0,1550.0,7572413.0,1022.5,1.62,8.45,10.0205,4076138.0,,7.776000000000002,1.62,6.185493827160493
BCS3_S63,266.34,-881.900569,-40.77,-6.0,4.32,1.0,-0.26,8748.0,325.48,288.66,198.44,-212.86,35.72,0.5,75.29,1.54,240.49,63.43,924.64,-881.530458,231.59,536.21,-881.59135,1.93,1.95,0.975,3220.0,400.0,2090.0,10777274.0,1087.0,1.32,7.18,10.6526,3565160.0,,19.008,1.32,8.070151515151515
BCS3_S67,266.34,-881.900569,-40.77,-6.0,4.32,1.0,-0.26,8748.0,325.48,288.66,198.44,-212.86,35.72,0.5,75.29,1.54,240.49,63.43,924.64,-881.530458,231.59,536.21,-881.59135,1.74,1.9,0.95,3130.0,585.0,1990.0,12896981.0,1448.5,2.1,15.4,14.1953,5001737.0,,50.4,2.1,6.759666666666666
BCS3_S71,266.34,-881.900569,-40.77,-6.0,4.32,1.0,-0.26,8748.0,325.48,288.66,198.44,-212.86,35.72,0.5,75.29,1.54,240.49,63.43,924.64,-881.530458,231.59,536.21,-881.59135,1.92,1.88,0.94,3685.0,500.0,2360.0,12461209.0,1491.5,2.4,18.48,14.6167,5261374.0,0.27585185185185185,11.52,2.4,6.090291666666666
BCS3_S75,266.34,-881.900569,-40.77,-6.0,4.32,1.0,-0.26,8748.0,325.48,288.66,198.44,-212.86,35.72,0.5,75.29,1.54,240.49,63.43,924.64,-881.530458,231.59,536.21,-881.59135,1.96,1.89,0.945,7215.0,1260.0,4795.0,23428800.0,1422.0,1.81,13.56,13.935599999999999,4962653.0,0.26299787685774945,8.688,1.81,7.6992265193370155
BCS3_S79,266.34,-881.900569,-40.77,-6.0,4.32,1.0,-0.26,8748.0,325.48,288.66,198.44,-212.86,35.72,0.5,75.29,1.54,240.49,63.43,924.64,-881.530458,231.59,536.21,-881.59135,2.14,1.95,0.975,3200.0,355.0,2025.0,8717022.0,1057.0,1.7,8.86,10.3586,3466766.0,0.1954913894786506,24.48,1.7,6.0932941176470585
BCS3_S83,266.34,-881.900569,-40.77,-6.0,4.32,1.0,-0.26,8748.0,325.48,288.66,198.44,-212.86,35.72,0.5,75.29,1.54,240.49,63.43,924.64,-881.530458,231.59,536.21,-881.59135,1.76,1.77,0.885,2280.0,250.0,1440.0,9201301.0,1077.5,2.58,16.46,10.5595,4295392.0,0.1992828497287096,61.92,2.58,4.092829457364341
BCS3_S87,266.34,-881.900569,-40.77,-6.0,4.32,1.0,-0.26,8748.0,325.48,288.66,198.44,-212.86,35.72,0.5,75.29,1.54,240.49,63.43,924.64,-881.530458,231.59,536.21,-881.59135,2.03,1.92,0.96,2875.0,375.0,1810.0,8701889.0,1441.0,1.92,15.15,14.1218,5195361.0,0.03331398914838406,9.216,1.92,7.355104166666667
BCS3_S91,266.34,-881.900569,-40.77,-6.0,4.32,1.0,-0.26,8748.0,325.48,288.66,198.44,-212.86,35.72,0.5,75.29,1.54,240.49,63.43,924.64,-881.530458,231.59,536.21,-881.59135,2.08,1.96,0.98,3750.0,605.0,2405.0,10816158.0,1351.0,5.51,110.6,13.239799999999999,4387015.0,0.03123330974286388,79.344,5.51,2.402867513611615
BCS3_S95,266.34,-881.900569,-40.77,-6.0,4.32,1.0,-0.26,8748.0,325.48,288.66,198.44,-212.86,35.72,0.5,75.29,1.54,240.49,63.43,924.64,-881.530458,231.59,536.21,-881.59135,2.01,1.99,0.995,2520.0,510.0,1790.0,7811291.0,1764.5,3.8,161.25,17.292099999999998,5563934.0,0.040792875678225995,54.72,3.8,4.550552631578947
BCS3_S99,266.34,-881.900569,-40.77,-6.0,4.32,1.0,-0.26,8748.0,325.48,288.66,198.44,-212.86,35.72,0.5,75.29,1.54,240.49,63.43,924.64,-881.530458,231.59,536.21,-881.59135,1.96,1.86,0.93,3635.0,535.0,2560.0,11803700.0,951.0,3.23,16.9,9.319799999999999,3428722.0,0.021985845718329792,77.52,3.23,2.8853869969040247
BCS3_S103,266.34,-881.900569,-40.77,-6.0,4.32,1.0,-0.26,8748.0,325.48,288.66,198.44,-212.86,35.72,0.5,75.29,1.54,240.49,63.43,924.64,-881.530458,231.59,536.21,-881.59135,1.77,1.91,0.955,4710.0,630.0,2860.0,18776148.0,1416.5,2.02,15.1,13.8817,4840111.0,0.26198065581505076,29.088,2.02,6.872128712871287
BCS3_S107,266.34,-881.900569,-40.77,-6.0,4.32,1.0,-0.26,8748.0,325.48,288.66,198.44,-212.86,35.72,0.5,75.29,1.54,240.49,63.43,924.64,-881.530458,231.59,536.21,-881.59135,1.91,1.97,0.985,850.0,170.0,500.0,2904409.0,520.0,0.86,2.43,5.096,1671953.0,0.09617362585515452,12.384,0.86,5.925581395348837
BCS3_S111,297.74,-1993.12989,-142.83,-6.67,5.13,20.0,-1.52,24.0,250.81,219.68,168.51,-171.02,3965.0,-0.63,122.626,1.42,280.89,57.98,445.98,-1992.94523,184.53,483.64,-1993.00015,1.78,1.81,0.905,2660.0,345.0,1730.0,10476180.0,1030.0,1.97,9.88,10.094,3930292.0,108.42462365653616,3.4230720000000003,1.97,5.123857868020305
BCS3_S115,297.74,-1993.12989,-142.83,-6.67,5.13,20.0,-1.52,24.0,250.81,219.68,168.51,-171.02,3965.0,-0.63,122.626,1.42,280.89,57.98,445.98,-1992.94523,184.53,483.64,-1993.00015,169.0,1.82,0.91,5405.0,570.0,3315.0,23662920.0,1524.0,2.04,17.01,14.9352,5748206.0,157.7964492071453,3.5642880000000003,2.04,7.321176470588235
BCS3_S119,297.74,-1993.12989,-142.83,-6.67,5.13,20.0,-1.52,24.0,250.81,219.68,168.51,-171.02,3965.0,-0.63,122.626,1.42,280.89,57.98,445.98,-1992.94523,184.53,483.64,-1993.00015,1.96,1.63,0.815,6755.0,970.0,4865.0,21935072.0,532.5,1.24,3.62,5.2185,2498584.0,76.7508549984211,1.940352,1.24,4.2084677419354835
BCS3_S123,297.74,-1993.12989,-142.83,-6.67,5.13,20.0,-1.52,24.0,250.81,219.68,168.51,-171.02,3965.0,-0.63,122.626,1.42,280.89,57.98,445.98,-1992.94523,184.53,483.64,-1993.00015,1.7,1.76,0.88,4975.0,415.0,2965.0,21492548.0,598.5,0.99,3.44,5.8652999999999995,2415342.0,68.52555704070497,1.6727040000000002,0.99,5.924545454545454
BCS3_S127,297.74,-1993.12989,-142.83,-6.67,5.13,20.0,-1.52,24.0,250.81,219.68,168.51,-171.02,3965.0,-0.63,122.626,1.42,280.89,57.98,445.98,-1992.94523,184.53,483.64,-1993.00015,1.62,1.85,0.925,6410.0,535.0,4155.0,30514868.0,1193.0,1.8,11.59,11.6914,4349195.0,117.61201259323927,3.1968,1.8,6.495222222222222
BCS3_S131,297.74,-1993.12989,-142.83,-6.67,5.13,20.0,-1.52,24.0,250.81,219.68,168.51,-171.02,3965.0,-0.63,122.626,1.42,280.89,57.98,445.98,-1992.94523,184.53,483.64,-1993.00015,1.93,1.72,0.86,5330.0,375.0,3320.0,17839400.0,692.5,1.03,4.06,6.7865,2927200.0,84.94950650902106,1.700736,1.03,6.5888349514563105
BCS3_S135,297.74,-1993.12989,-142.83,-6.67,5.13,20.0,-1.52,24.0,250.81,219.68,168.51,-171.02,3965.0,-0.63,122.626,1.42,280.89,57.98,445.98,-1992.94523,184.53,483.64,-1993.00015,1.7,1.85,0.925,5315.0,420.0,3140.0,22961384.0,754.0,1.03,4.1,7.3892,2748778.0,74.3331580010917,1.82928,1.03,7.173980582524272
BCS3_S139,297.74,-1993.12989,-142.83,-6.67,5.13,20.0,-1.52,24.0,250.81,219.68,168.51,-171.02,3965.0,-0.63,122.626,1.42,280.89,57.98,445.98,-1992.94523,184.53,483.64,-1993.00015,1.81,1.91,0.955,2475.0,180.0,1170.0,9444147.0,719.0,0.92,3.84,7.0462,2456788.0,64.4102836821607,1.686912,0.92,7.65891304347826
BCS3_S143,297.74,-1993.12989,-142.83,-6.67,5.13,20.0,-1.52,24.0,250.81,219.68,168.51,-171.02,3965.0,-0.63,122.626,1.42,280.89,57.98,445.98,-1992.94523,184.53,483.64,-1993.00015,1.87,1.91,0.955,6625.0,620.0,4075.0,23625112.0,905.5,1.12,6.14,8.873899999999999,3094049.0,81.11754085423713,2.0536320000000003,1.12,7.923124999999998
BCS3_S147,297.74,-1993.12989,-142.83,-6.67,5.13,20.0,-1.52,24.0,250.81,219.68,168.51,-171.02,3965.0,-0.63,122.626,1.42,280.89,57.98,445.98,-1992.94523,184.53,483.64,-1993.00015,1.79,1.8,0.9,4735.0,430.0,2565.0,18426384.0,739.0,1.06,4.46,7.2421999999999995,2853195.0,79.09578604317929,1.83168,1.06,6.832264150943395
BCS3_S151,297.74,-1993.12989,-142.83,-6.67,5.13,20.0,-1.52,24.0,250.81,219.68,168.51,-171.02,3965.0,-0.63,122.626,1.42,280.89,57.98,445.98,-1992.94523,184.53,483.64,-1993.00015,1.84,1.8,0.9,1500.0,135.0,740.0,5530066.0,482.0,0.69,1.98,4.7236,1664368.0,51.588861803535075,1.1923199999999998,0.69,6.845797101449277
BCS3_S155,297.74,-1993.12989,-142.83,-6.67,5.13,20.0,-1.52,24.0,250.81,219.68,168.51,-171.02,3965.0,-0.63,122.626,1.42,280.89,57.98,445.98,-1992.94523,184.53,483.64,-1993.00015,1.82,,0.0,7575.0,725.0,4445.0,28571298.0,,,,,,,,,
BCS3_S159,297.74,-1993.12989,-142.83,-6.67,5.13,20.0,-1.52,24.0,250.81,219.68,168.51,-171.02,3965.0,-0.63,122.626,1.42,280.89,57.98,445.98,-1992.94523,184.53,483.64,-1993.00015,,,0.0,,,,,,,,,,,,,
BCS3_S163,297.74,-1993.12989,-142.83,-6.67,5.13,20.0,-1.52,24.0,250.81,219.68,168.51,-171.02,3965.0,-0.63,122.626,1.42,280.89,57.98,445.98,-1992.94523,184.53,483.64,-1993.00015,1.85,1.77,0.885,6380.0,465.0,3485.0,23258896.0,740.5,1.27,5.06,7.2569,2951961.0,83.3550059909666,2.157984,1.27,5.714094488188977
BCS4_S2,222.25,-1396.99167,-87.92,-7.23,2.95,11.0,-1.97,24.0,204.81,168.57,152.18,-149.99,40.07,-0.64,107.179,1.39,263.87,53.8,326.98,-1396.85486,145.73,438.43,-1396.90465,1.91,1.61,0.805,12085.0,5195.0,9550.0,41293856.0,1040.5,2.92,16.86,10.1969,5001872.0,155.62912644346758,0.0,2.92,3.4920890410958902
BCS4_S6,222.25,-1396.99167,-87.92,-7.23,2.95,11.0,-1.97,24.0,204.81,168.57,152.18,-149.99,40.07,-0.64,107.179,1.39,263.87,53.8,326.98,-1396.85486,145.73,438.43,-1396.90465,1.87,1.91,0.955,8530.0,2715.0,8050.0,30418444.0,1257.0,1.35,9.31,12.3186,4295108.0,112.60601750831152,2.47536,1.35,9.124888888888888
BCS4_S10,222.25,-1396.99167,-87.92,-7.23,2.95,11.0,-1.97,24.0,204.81,168.57,152.18,-149.99,40.07,-0.64,107.179,1.39,263.87,53.8,326.98,-1396.85486,145.73,438.43,-1396.90465,1.8,1.7,0.85,8765.0,1285.0,5345.0,33840664.0,754.5,1.25,5.86,7.3941,3259523.0,95.8603263666783,2.04,1.25,5.91528
BCS4_S14,222.25,-1396.99167,-87.92,-7.23,2.95,11.0,-1.97,24.0,204.81,168.57,152.18,-149.99,40.07,-0.64,107.179,1.39,263.87,53.8,326.98,-1396.85486,145.73,438.43,-1396.90465,1.91,1.77,0.885,12790.0,3070.0,9335.0,43702808.0,910.0,3.27,8.84,8.918,3627663.0,102.43491620766996,5.556384,3.27,2.727217125382263
BCS4_S18,222.25,-1396.99167,-87.92,-7.23,2.95,11.0,-1.97,24.0,204.81,168.57,152.18,-149.99,40.07,-0.64,107.179,1.39,263.87,53.8,326.98,-1396.85486,145.73,438.43,-1396.90465,1.74,2.01,1.005,4680.0,955.0,2850.0,19283664.0,1172.5,2.12,13.28,11.490499999999999,3627223.0,90.12620874880072,4.090751999999999,2.12,5.42004716981132
BCS4_S22,222.25,-1396.99167,-87.92,-7.23,2.95,11.0,-1.97,24.0,204.81,168.57,152.18,-149.99,40.07,-0.64,107.179,1.39,263.87,53.8,326.98,-1396.85486,145.73,438.43,-1396.90465,1.91,1.95,0.975,8590.0,1930.0,6095.0,29351612.0,809.5,1.13,5.63,7.9331,2655011.0,68.14585460045829,2.1153599999999995,1.13,7.020442477876107
BCS4_S26,222.25,-1396.99167,-87.92,-7.23,2.95,11.0,-1.97,24.0,204.81,168.57,152.18,-149.99,40.07,-0.64,107.179,1.39,263.87,53.8,326.98,-1396.85486,145.73,438.43,-1396.90465,,,0.0,,,,,,,,,,,,,
[...]
BCS4_S119,416.57,-1632.91059,-51.02,-6.49,2.85,0.0,-1.5,1152.0,420.23,423.04,236.46,-187.43,34.5,3.74,50.992,1.54,137.0,74.51,1380.64,-1632.36094,334.33,633.17,-1632.43284,1.94,2.09,1.045,5895.0,1235.0,3925.0,19530474.0,1340.0,1.51,11.54,13.132,3831169.0,91.6204379335117,3.029664,1.51,8.696688741721854
BCS4_S120,416.57,-1632.91059,-51.02,-6.49,2.85,0.0,-1.5,1152.0,420.23,423.04,236.46,-187.43,34.5,3.74,50.992,1.54,137.0,74.51,1380.64,-1632.36094,334.33,633.17,-1632.43284,2.2,1.96,0.98,7995.0,1215.0,5520.0,20632676.0,857.0,1.24,5.9,8.3986,2782880.0,71.0459017872065,2.333184,1.24,6.773064516129033
BCS4_S121,416.57,-1632.91059,-51.02,-6.49,2.85,0.0,-1.5,1152.0,420.23,423.04,236.46,-187.43,34.5,3.74,50.992,1.54,137.0,74.51,1380.64,-1632.36094,334.33,633.17,-1632.43284,2.17,1.91,0.955,7750.0,2035.0,6030.0,50540956.0,203.0,0.95,1.02,1.9893999999999998,693641.0,18.185379120276245,1.7419200000000001,0.95,2.0941052631578945
BCS4_S122,416.57,-1632.91059,-51.02,-6.49,2.85,0.0,-1.5,1152.0,420.23,423.04,236.46,-187.43,34.5,3.74,50.992,1.54,137.0,74.51,1380.64,-1632.36094,334.33,633.17,-1632.43284,1.9,1.7,0.85,2365.0,475.0,1635.0,8166453.0,527.5,2.03,4.77,5.1695,2278858.0,67.01964500784997,3.312959999999999,2.03,2.5465517241379314
BCS4_S123,416.57,-1632.91059,-51.02,-6.49,2.85,0.0,-1.5,1152.0,420.23,423.04,236.46,-187.43,34.5,3.74,50.992,1.54,137.0,74.51,1380.64,-1632.36094,334.33,633.17,-1632.43284,1.87,1.74,0.87,5445.0,1780.0,5445.0,19417168.0,589.0,1.22,3.88,5.7722,2426940.0,69.79012452399874,2.037888,1.22,4.731311475409836
BCS4_S124,416.57,-1632.91059,-51.02,-6.49,2.85,0.0,-1.5,1152.0,420.23,423.04,236.46,-187.43,34.5,3.74,50.992,1.54,137.0,74.51,1380.64,-1632.36094,334.33,633.17,-1632.43284,1.9,2.21,1.105,8460.0,2325.0,7650.0,25212768.0,400.5,0.9,2.24,3.9249,1022803.0,23.160723542136445,1.9094400000000002,0.9,4.361
BCS4_S125,416.57,-1632.91059,-51.02,-6.49,2.85,0.0,-1.5,1152.0,420.23,423.04,236.46,-187.43,34.5,3.74,50.992,1.54,137.0,74.51,1380.64,-1632.36094,334.33,633.17,-1632.43284,1.93,1.82,0.91,4715.0,1195.0,3255.0,15781008.0,355.0,1.84,3.63,3.479,1338985.0,36.757046895365214,3.214848,1.84,1.8907608695652174
BCS4_S126,416.57,-1632.91059,-51.02,-6.49,2.85,0.0,-1.5,1152.0,420.23,423.04,236.46,-187.43,34.5,3.74,50.992,1.54,137.0,74.51,1380.64,-1632.36094,334.33,633.17,-1632.43284,1.81,1.7,0.85,6745.0,680.0,4170.0,25737686.0,710.0,1.52,6.14,6.958,3067278.0,90.2065364086701,2.4806399999999997,1.52,4.5776315789473685
BCS4_S127,416.57,-1632.91059,-51.02,-6.49,2.85,0.0,-1.5,1152.0,420.23,423.04,236.46,-187.43,34.5,3.74,50.992,1.54,137.0,74.51,1380.64,-1632.36094,334.33,633.17,-1632.43284,1.86,1.76,0.88,7190.0,1395.0,4695.0,25922726.0,1380.0,1.91,14.42,13.524,5593423.0,158.00379067029718,3.2271360000000002,1.91,7.0806282722513085
BCS4_S128,416.57,-1632.91059,-51.02,-6.49,2.85,0.0,-1.5,1152.0,420.23,423.04,236.46,-187.43,34.5,3.74,50.992,1.54,137.0,74.51,1380.64,-1632.36094,334.33,633.17,-1632.43284,2.0,1.89,0.945,8905.0,2705.0,7145.0,27811534.0,1395.5,1.82,14.14,13.6759,4870171.0,129.02410393083423,3.3022080000000003,1.82,7.514230769230769
BCS4_S129,416.57,-1632.91059,-51.02,-6.49,2.85,0.0,-1.5,1152.0,420.23,423.04,236.46,-187.43,34.5,3.74,50.992,1.54,137.0,74.51,1380.64,-1632.36094,334.33,633.17,-1632.43284,1.78,1.79,0.895,8920.0,1095.0,5550.0,35130648.0,1221.0,1.4,9.92,11.9658,4751555.0,132.88715213556478,2.4057600000000003,1.4,8.547
BCS4_S130,416.57,-1632.91059,-51.02,-6.49,2.85,0.0,-1.5,1152.0,420.23,423.04,236.46,-187.43,34.5,3.74,50.992,1.54,137.0,74.51,1380.64,-1632.36094,334.33,633.17,-1632.43284,1.8,2.02,1.01,10810.0,1225.0,6980.0,41736176.0,1324.5,1.93,13.05,12.9801,4059034.0,100.30539155346828,3.7426559999999998,1.93,6.725440414507772
BCS4_S131,416.57,-1632.91059,-51.02,-6.49,2.85,0.0,-1.5,1152.0,420.23,423.04,236.46,-187.43,34.5,3.74,50.992,1.54,137.0,74.51,1380.64,-1632.36094,334.33,633.17,-1632.43284,1.98,1.78,0.89,3850.0,990.0,2725.0,12258313.0,807.5,2.32,10.31,7.9135,3180269.0,89.37353734477351,3.9644160000000004,2.32,3.410991379310345
BCS4_S132,416.57,-1632.91059,-51.02,-6.49,2.85,0.0,-1.5,1152.0,420.23,423.04,236.46,-187.43,34.5,3.74,50.992,1.54,137.0,74.51,1380.64,-1632.36094,334.33,633.17,-1632.43284,1.77,2.17,1.085,4965.0,1275.0,3390.0,19792690.0,944.0,1.82,9.42,9.251199999999999,2502021.0,57.66591879142008,3.7914239999999997,1.82,5.083076923076923
BCS4_S133,416.57,-1632.91059,-51.02,-6.49,2.85,0.0,-1.5,1152.0,420.23,423.04,236.46,-187.43,34.5,3.74,50.992,1.54,137.0,74.51,1380.64,-1632.36094,334.33,633.17,-1632.43284,1.92,1.96,0.98,4035.0,1145.0,3075.0,13644770.0,1092.5,2.12,12.59,10.7065,3547604.0,90.56901715580292,3.9889919999999996,2.12,5.0502358490566035
BCS4_S134,416.57,-1632.91059,-51.02,-6.49,2.85,0.0,-1.5,1152.0,420.23,423.04,236.46,-187.43,34.5,3.74,50.992,1.54,137.0,74.51,1380.64,-1632.36094,334.33,633.17,-1632.43284,1.96,1.82,0.91,4700.0,1135.0,3145.0,15262005.0,735.0,1.73,6.63,7.202999999999999,2772265.0,76.10261821998148,3.022656,1.73,4.163583815028901
BCS4_S135,416.57,-1632.91059,-51.02,-6.49,2.85,0.0,-1.5,1152.0,420.23,423.04,236.46,-187.43,34.5,3.74,50.992,1.54,137.0,74.51,1380.64,-1632.36094,334.33,633.17,-1632.43284,1.92,1.82,0.91,4725.0,1165.0,3165.0,15978076.0,780.5,2.03,8.24,7.648899999999999,2943881.0,80.81373268121844,3.5468159999999997,2.03,3.767931034482759
BCS4_S136,416.57,-1632.91059,-51.02,-6.49,2.85,0.0,-1.5,1152.0,420.23,423.04,236.46,-187.43,34.5,3.74,50.992,1.54,137.0,74.51,1380.64,-1632.36094,334.33,633.17,-1632.43284,1.98,1.78,0.89,1805.0,515.0,1070.0,5747079.0,428.5,1.24,3.03,4.1993,1687610.0,47.426081426916966,2.118912,1.24,3.3865322580645163
BCS4_S137,416.57,-1632.91059,-51.02,-6.49,2.85,0.0,-1.5,1152.0,420.23,423.04,236.46,-187.43,34.5,3.74,50.992,1.54,137.0,74.51,1380.64,-1632.36094,334.33,633.17,-1632.43284,1.74,1.74,0.87,3720.0,1090.0,2565.0,15328041.0,414.0,1.24,3.01,4.0572,1705863.0,49.05451876559504,2.071296,1.24,3.2719354838709678
BCS4_S138,416.57,-1632.91059,-51.02,-6.49,2.85,0.0,-1.5,1152.0,420.23,423.04,236.46,-187.43,34.5,3.74,50.992,1.54,137.0,74.51,1380.64,-1632.36094,334.33,633.17,-1632.43284,1.81,1.9,0.95,4530.0,890.0,2795.0,17285652.0,188.0,0.75,0.86,1.8424,649173.0,17.108954435243852,1.368,0.75,2.4565333333333332
BCS4_S139,416.57,-1632.91059,-51.02,-6.49,2.85,0.0,-1.5,1152.0,420.23,423.04,236.46,-187.43,34.5,3.74,50.992,1.54,137.0,74.51,1380.64,-1632.36094,334.33,633.17,-1632.43284,1.7,1.87,0.935,2310.0,465.0,1700.0,9979454.0,345.0,1.04,2.13,3.381,1230289.0,32.932196549233524,1.8670080000000002,1.04,3.2509615384615382
BCS4_S140,416.57,-1632.91059,-51.02,-6.49,2.85,0.0,-1.5,1152.0,420.23,423.04,236.46,-187.43,34.5,3.74,50.992,1.54,137.0,74.51,1380.64,-1632.36094,334.33,633.17,-1632.43284,1.91,1.42,0.71,1760.0,480.0,1470.0,6013834.0,141.0,0.75,0.58,1.3818,875150.0,30.73834656293855,1.0224,0.75,1.8423999999999998
BCS4_S141,416.57,-1632.91059,-51.02,-6.49,2.85,0.0,-1.5,1152.0,420.23,423.04,236.46,-187.43,34.5,3.74,50.992,1.54,137.0,74.51,1380.64,-1632.36094,334.33,633.17,-1632.43284,2.08,2.22,1.11,9575.0,2810.0,7420.0,27617256.0,1225.0,1.73,11.63,12.004999999999999,3104172.0,69.88815710603428,3.686976,1.73,6.9393063583815024
BCS4_S142,416.57,-1632.91059,-51.02,-6.49,2.85,0.0,-1.5,1152.0,420.23,423.04,236.46,-187.43,34.5,3.74,50.992,1.54,137.0,74.51,1380.64,-1632.36094,334.33,633.17,-1632.43284,2.02,1.91,0.955,5210.0,900.0,3070.0,15966452.0,1364.0,2.44,19.0,13.3672,4660721.0,122.19141438451625,4.473984,2.44,5.478360655737705
BCS4_S143,416.57,-1632.91059,-51.02,-6.49,2.85,0.0,-1.5,1152.0,420.23,423.04,236.46,-187.43,34.5,3.74,50.992,1.54,137.0,74.51,1380.64,-1632.36094,334.33,633.17,-1632.43284,1.91,2.13,1.065,8045.0,1785.0,5245.0,27489372.0,1437.0,2.61,17.98,14.0826,3958471.0,92.82060207185226,5.3369279999999995,2.61,5.395632183908046
BCS4_S144,416.57,-1632.91059,-51.02,-6.49,2.85,0.0,-1.5,1152.0,420.23,423.04,236.46,-187.43,34.5,3.74,50.992,1.54,137.0,74.51,1380.64,-1632.36094,334.33,633.17,-1632.43284,2.08,2.03,1.015,7635.0,1985.0,5665.0,22021698.0,1582.5,2.18,19.24,15.5085,4789822.0,118.08154536172522,4.248384,2.18,7.113990825688073
BCS4_S145,416.57,-1632.91059,-51.02,-6.49,2.85,0.0,-1.5,1152.0,420.23,423.04,236.46,-187.43,34.5,3.74,50.992,1.54,137.0,74.51,1380.64,-1632.36094,334.33,633.17,-1632.43284,1.94,1.87,0.935,6245.0,1305.0,4180.0,20690044.0,1139.5,2.22,13.05,11.1671,4063519.0,108.77170425464234,3.985344000000001,2.22,5.030225225225225
BCS4_S146,416.57,-1632.91059,-51.02,-6.49,2.85,0.0,-1.5,1152.0,420.23,423.04,236.46,-187.43,34.5,3.74,50.992,1.54,137.0,74.51,1380.64,-1632.36094,334.33,633.17,-1632.43284,1.89,2.15,1.075,7360.0,2440.0,5320.0,25685744.0,823.0,1.33,6.06,8.0654,2223381.0,51.690517335372235,2.7451199999999996,1.33,6.064210526315789
BCS4_S147,416.57,-1632.91059,-51.02,-6.49,2.85,0.0,-1.5,1152.0,420.23,423.04,236.46,-187.43,34.5,3.74,50.992,1.54,137.0,74.51,1380.64,-1632.36094,334.33,633.17,-1632.43284,1.8,2.06,1.03,3605.0,1270.0,2980.0,13918493.0,797.0,1.77,6.6,7.8106,2347117.0,56.909279017068364,3.5003520000000004,1.77,4.412768361581921
BCS4_S148,416.57,-1632.91059,-51.02,-6.49,2.85,0.0,-1.5,1152.0,420.23,423.04,236.46,-187.43,34.5,3.74,50.992,1.54,137.0,74.51,1380.64,-1632.36094,334.33,633.17,-1632.43284,2.0,1.95,0.975,7160.0,3315.0,0.0,22361660.0,1140.0,1.93,11.91,11.171999999999999,3738990.0,95.96822019088629,3.6129599999999997,1.93,5.78860103626943
BCS4_S149,416.57,-1632.91059,-51.02,-6.49,2.85,0.0,-1.5,1152.0,420.23,423.04,236.46,-187.43,34.5,3.74,50.992,1.54,137.0,74.51,1380.64,-1632.36094,334.33,633.17,-1632.43284,1.88,1.8,0.9,6515.0,860.0,4420.0,22982132.0,808.0,1.94,8.87,7.9184,3119596.0,86.48091356277249,3.3523200000000006,1.94,4.081649484536083
BCS4_S150,416.57,-1632.91059,-51.02,-6.49,2.85,0.0,-1.5,1152.0,420.23,423.04,236.46,-187.43,34.5,3.74,50.992,1.54,137.0,74.51,1380.64,-1632.36094,334.33,633.17,-1632.43284,1.94,1.64,0.82,4845.0,545.0,2485.0,16051763.0,162.5,0.96,0.95,1.5925,755251.0,22.995785260277234,1.5114239999999999,0.96,1.6588541666666667
BCS4_S151,416.57,-1632.91059,-51.02,-6.49,2.85,0.0,-1.5,1152.0,420.23,423.04,236.46,-187.43,34.5,3.74,50.992,1.54,137.0,74.51,1380.64,-1632.36094,334.33,633.17,-1632.43284,2.0,2.11,1.055,7375.0,1260.0,4910.0,23033136.0,505.5,0.89,2.73,4.9539,1416360.0,33.589243081212096,1.802784,0.89,5.566179775280899
BCS4_S152,416.57,-1632.91059,-51.02,-6.49,2.85,0.0,-1.5,1152.0,420.23,423.04,236.46,-187.43,34.5,3.74,50.992,1.54,137.0,74.51,1380.64,-1632.36094,334.33,633.17,-1632.43284,2.0,1.99,0.995,1715.0,640.0,1210.0,5356180.0,413.0,0.74,1.93,4.0474,1302298.0,32.712764390619164,1.4136959999999998,0.74,5.469459459459459
BCS4_S153,416.57,-1632.91059,-51.02,-6.49,2.85,0.0,-1.5,1152.0,420.23,423.04,236.46,-187.43,34.5,3.74,50.992,1.54,137.0,74.51,1380.64,-1632.36094,334.33,633.17,-1632.43284,2.1,1.91,0.955,1235.0,240.0,725.0,3500351.0,510.0,1.02,2.71,4.998,1742645.0,45.687405671629975,1.8702719999999997,1.02,4.9
BCS4_S154,416.57,-1632.91059,-51.02,-6.49,2.85,0.0,-1.5,1152.0,420.23,423.04,236.46,-187.43,34.5,3.74,50.992,1.54,137.0,74.51,1380.64,-1632.36094,334.33,633.17,-1632.43284,1.95,1.91,0.955,4860.0,995.0,3195.0,15939906.0,753.0,1.05,4.51,7.3793999999999995,2572964.0,67.45611072693602,1.9252799999999999,1.05,7.028
BCS4_S155,416.57,-1632.91059,-51.02,-6.49,2.85,0.0,-1.5,1152.0,420.23,423.04,236.46,-187.43,34.5,3.74,50.992,1.54,137.0,74.51,1380.64,-1632.36094,334.33,633.17,-1632.43284,2.15,1.87,0.935,7470.0,535.0,4750.0,20180628.0,560.5,1.11,3.65,5.4929,1998774.0,53.50288743723302,1.9926720000000004,1.11,4.948558558558558
BCS4_S156,416.57,-1632.91059,-51.02,-6.49,2.85,0.0,-1.5,1152.0,420.23,423.04,236.46,-187.43,34.5,3.74,50.992,1.54,137.0,74.51,1380.64,-1632.36094,334.33,633.17,-1632.43284,1.97,1.91,0.955,8855.0,2215.0,6050.0,28471438.0,846.5,1.92,9.47,8.2957,2892449.0,75.83213510006819,3.5205119999999996,1.92,4.320677083333334
BCS4_S157,416.57,-1632.91059,-51.02,-6.49,2.85,0.0,-1.5,1152.0,420.23,423.04,236.46,-187.43,34.5,3.74,50.992,1.54,137.0,74.51,1380.64,-1632.36094,334.33,633.17,-1632.43284,2.07,1.98,0.99,7235.0,2360.0,4940.0,21053744.0,895.0,1.33,6.24,8.770999999999999,2849660.0,71.970395257308,2.528064,1.33,6.594736842105262
BCS4_S158,416.57,-1632.91059,-51.02,-6.49,2.85,0.0,-1.5,1152.0,420.23,423.04,236.46,-187.43,34.5,3.74,50.992,1.54,137.0,74.51,1380.64,-1632.36094,334.33,633.17,-1632.43284,2.07,2.15,1.075,6440.0,2160.0,4330.0,18740304.0,1555.5,1.7,13.4,15.2439,4202271.0,97.69696198684265,3.5088,1.7,8.967
BCS4_S159,416.57,-1632.91059,-51.02,-6.49,2.85,0.0,-1.5,1152.0,420.23,423.04,236.46,-187.43,34.5,3.74,50.992,1.54,137.0,74.51,1380.64,-1632.36094,334.33,633.17,-1632.43284,2.04,2.1,1.05,8265.0,2240.0,6190.0,24786532.0,1161.0,1.4,8.67,11.377799999999999,3290613.0,78.25295723384895,2.8224,1.4,8.126999999999999
BCS4_S160,416.57,-1632.91059,-51.02,-6.49,2.85,0.0,-1.5,1152.0,420.23,423.04,236.46,-187.43,34.5,3.74,50.992,1.54,137.0,74.51,1380.64,-1632.36094,334.33,633.17,-1632.43284,1.97,,,6035.0,2325.0,5370.0,19404306.0,,,,,,,,,
BCS4_S161,416.57,-1632.91059,-51.02,-6.49,2.85,0.0,-1.5,1152.0,420.23,423.04,236.46,-187.43,34.5,3.74,50.992,1.54,137.0,74.51,1380.64,-1632.36094,334.33,633.17,-1632.43284,2.02,2.13,1.065,4925.0,985.0,3310.0,15093047.0,870.5,1.02,4.7,8.530899999999999,2397946.0,56.22848580622643,2.085696,1.02,8.363627450980392
BCS4_S162,416.57,-1632.91059,-51.02,-6.49,2.85,0.0,-1.5,1152.0,420.23,423.04,236.46,-187.43,34.5,3.74,50.992,1.54,137.0,74.51,1380.64,-1632.36094,334.33,633.17,-1632.43284,2.02,2.04,1.02,3605.0,670.0,2540.0,11047804.0,670.5,1.03,3.99,6.5709,2010813.0,49.298613280853296,2.017152,1.03,6.379514563106796
BCS4_S163,416.57,-1632.91059,-51.02,-6.49,2.85,0.0,-1.5,1152.0,420.23,423.04,236.46,-187.43,34.5,3.74,50.992,1.54,137.0,74.51,1380.64,-1632.36094,334.33,633.17,-1632.43284,2.13,2.03,1.015,8325.0,1710.0,5855.0,22932686.0,913.0,1.22,6.38,8.9474,2763417.0,68.12540342196218,2.3775359999999996,1.22,7.333934426229509
BCS4_S164,416.57,-1632.91059,-51.02,-6.49,2.85,0.0,-1.5,1152.0,420.23,423.04,236.46,-187.43,34.5,3.74,50.992,1.54,137.0,74.51,1380.64,-1632.36094,334.33,633.17,-1632.43284,1.98,2.15,1.075,8025.0,1670.0,5625.0,25551418.0,950.5,1.2,6.37,9.3149,2567829.0,59.69846503921179,2.4768,1.2,7.762416666666667
BCS4_S165,416.57,-1632.91059,-51.02,-6.49,2.85,0.0,-1.5,1152.0,420.23,423.04,236.46,-187.43,34.5,3.74,50.992,1.54,137.0,74.51,1380.64,-1632.36094,334.33,633.17,-1632.43284,1.99,2.1,1.05,4860.0,965.0,3085.0,15324861.0,1181.0,1.3,8.09,11.5738,3347299.0,79.60098405958279,2.6208,1.3,8.902923076923077
PS-S1,296.15,-1665.24248,-163.68,-6.18,6.76,1.0,-1.16,24.0,280.97,266.6,197.82,-222.78,36.91,3.6,36.776,1.4,202.02,61.81,587.93,-1665.00384,197.4,438.59,-1665.05876,1.76,1.76,0.88,1270.0,245.0,775.0,5125290.0,663.5,1.82,6.51,6.5023,2677660.0,75.9678,3.07507,1.82,3.57269
PS-S2,296.15,-1665.24248,-163.68,-6.18,6.76,1.0,-1.16,24.0,280.97,266.6,197.82,-222.78,36.91,3.6,36.776,1.4,202.02,61.81,587.93,-1665.00384,197.4,438.59,-1665.05876,1.83,1.65,0.825,1855.0,480.0,1295.0,6916860.0,672.0,2.14,7.77,6.5856,3079470.0,93.3778,3.38976,2.14,3.07738
PS-S3,296.15,-1665.24248,-163.68,-6.18,6.76,1.0,-1.16,24.0,280.97,266.6,197.82,-222.78,36.91,3.6,36.776,1.4,202.02,61.81,587.93,-1665.00384,197.4,438.59,-1665.05876,1.8,1.68,0.84,2540.0,785.0,1975.0,9806650.0,532.0,1.59,4.89,5.2136,2350060.0,70.0342,2.56435,1.59,3.27899
PS-S4,296.15,-1665.24248,-163.68,-6.18,6.76,1.0,-1.16,24.0,280.97,266.6,197.82,-222.78,36.91,3.6,36.776,1.4,202.02,61.81,587.93,-1665.00384,197.4,438.59,-1665.05876,1.82,1.81,0.905,2640.0,505.0,1985.0,9957520.0,764.5,1.63,6.53,7.4921,2917190.0,80.4763,2.83229,1.63,4.59638
PS-S5,296.15,-1665.24248,-163.68,-6.18,6.76,1.0,-1.16,24.0,280.97,266.6,197.82,-222.78,36.91,3.6,36.776,1.4,202.02,61.81,587.93,-1665.00384,197.4,438.59,-1665.05876,1.71,1.91,0.955,3080.0,570.0,2070.0,13132400.0,753.0,1.61,6.69,7.3794,2572960.0,67.4561,2.9521,1.61,4.58348
PS-S6,296.15,-1665.24248,-163.68,-6.18,6.76,1.0,-1.16,24.0,280.97,266.6,197.82,-222.78,36.91,3.6,36.776,1.4,202.02,61.81,587.93,-1665.00384,197.4,438.59,-1665.05876,1.8,1.7,0.85,1270.0,365.0,860.0,4903330.0,371.0,5.88,14.79,3.6358,1602760.0,47.1361,9.59616,5.88,0.618333
PS-S7,296.15,-1665.24248,-163.68,-6.18,6.76,1.0,-1.16,24.0,280.97,266.6,197.82,-222.78,36.91,3.6,36.776,1.4,202.02,61.81,587.93,-1665.00384,197.4,438.59,-1665.05876,1.84,1.67,0.835,1320.0,415.0,920.0,4866460.0,346.0,6.07,16.9,3.3908,1551600.0,46.3717,9.73142,6.07,0.558616
PS-S8,296.15,-1665.24248,-163.68,-6.18,6.76,1.0,-1.16,24.0,280.97,266.6,197.82,-222.78,36.91,3.6,36.776,1.4,202.02,61.81,587.93,-1665.00384,197.4,438.59,-1665.05876,1.85,1.64,0.82,1295.0,420.0,940.0,4721050.0,326.0,6.12,15.19,3.1948,1515150.0,46.1331,9.63533,6.12,0.522026
PS-S9,296.15,-1665.24248,-163.68,-6.18,6.76,1.0,-1.16,24.0,280.97,266.6,197.82,-222.78,36.91,3.6,36.776,1.4,202.02,61.81,587.93,-1665.00384,197.4,438.59,-1665.05876,1.83,1.6,0.8,980.0,285.0,630.0,3654190.0,203.0,5.51,19.66,1.9894,990423.0,30.9359,8.46336,5.51,0.361053
PS-S10,296.15,-1665.24248,-163.68,-6.18,6.76,1.0,-1.16,24.0,280.97,266.6,197.82,-222.78,36.91,3.6,36.776,1.4,202.02,61.81,587.93,-1665.00384,197.4,438.59,-1665.05876,1.77,1.51,0.755,1645.0,445.0,1150.0,6557700.0,196.0,5.92,16.09,1.9208,1073800.0,35.5346,8.58163,5.92,0.324459
PS-S11,296.15,-1665.24248,-163.68,-6.18,6.76,1.0,-1.16,24.0,280.97,266.6,197.82,-222.78,36.91,3.6,36.776,1.4,202.02,61.81,587.93,-1665.00384,197.4,438.59,-1665.05876,1.77,1.86,0.93,2215.0,485.0,1645.0,8829870.0,372.0,1.41,3.01,3.6456,1341200.0,36.0853,2.5177,1.41,2.58553
PS-S12,296.15,-1665.24248,-163.68,-6.18,6.76,1.0,-1.16,24.0,280.97,266.6,197.82,-222.78,36.91,3.6,36.776,1.4,202.02,61.81,587.93,-1665.00384,197.4,438.59,-1665.05876,1.82,1.72,0.86,1835.0,435.0,1105.0,6921330.0,326.5,1.85,3.52,3.1997,1380120.0,40.052,3.05472,1.85,1.72957
PS-S13,296.15,-1665.24248,-163.68,-6.18,6.76,1.0,-1.16,24.0,280.97,266.6,197.82,-222.78,36.91,3.6,36.776,1.4,202.02,61.81,587.93,-1665.00384,197.4,438.59,-1665.05876,1.79,1.79,0.895,1820.0,435.0,1080.0,7082580.0,374.0,1.35,2.83,3.6652,1455430.0,40.7042,2.31984,1.35,2.71496
PS-S14,296.15,-1665.24248,-163.68,-6.18,6.76,1.0,-1.16,24.0,280.97,266.6,197.82,-222.78,36.91,3.6,36.776,1.4,202.02,61.81,587.93,-1665.00384,197.4,438.59,-1665.05876,1.76,1.84,0.92,2060.0,445.0,1380.0,8313460.0,395.5,1.53,3.51,3.8759,1458090.0,39.6296,2.70259,1.53,2.53327
PS-S15,296.15,-1665.24248,-163.68,-6.18,6.76,1.0,-1.16,24.0,280.97,266.6,197.82,-222.78,36.91,3.6,36.776,1.4,202.02,61.81,587.93,-1665.00384,197.4,438.59,-1665.05876,1.82,1.83,0.915,2045.0,440.0,1370.0,7713310.0,422.5,1.66,3.87,4.1405,1575400.0,43.0328,2.91629,1.66,2.49428
PS-S16,296.15,-1665.24248,-163.68,-6.18,6.76,1.0,-1.16,24.0,280.97,266.6,197.82,-222.78,36.91,3.6,36.776,1.4,202.02,61.81,587.93,-1665.00384,197.4,438.59,-1665.05876,1.78,1.86,0.93,1215.0,350.0,915.0,4785170.0,187.5,1.05,1.21,1.8375,676010.0,18.1882,1.87488,1.05,1.75
PS-S17,296.15,-1665.24248,-163.68,-6.18,6.76,1.0,-1.16,24.0,280.97,266.6,197.82,-222.78,36.91,3.6,36.776,1.4,202.02,61.81,587.93,-1665.00384,197.4,438.59,-1665.05876,1.86,1.86,0.93,1200.0,300.0,750.0,4326460.0,242.0,1.15,1.61,2.3716,872503.0,23.4749,2.05344,1.15,2.06226
PS-S18,296.15,-1665.24248,-163.68,-6.18,6.76,1.0,-1.16,24.0,280.97,266.6,197.82,-222.78,36.91,3.6,36.776,1.4,202.02,61.81,587.93,-1665.00384,197.4,438.59,-1665.05876,1.92,1.83,0.915,1480.0,425.0,1010.0,5004770.0,206.5,1.14,1.3,2.0237,769990.0,21.0326,2.00275,1.14,1.77518
PS-S19,296.15,-1665.24248,-163.68,-6.18,6.76,1.0,-1.16,24.0,280.97,266.6,197.82,-222.78,36.91,3.6,36.776,1.4,202.02,61.81,587.93,-1665.00384,197.4,438.59,-1665.05876,1.84,1.89,0.945,1150.0,265.0,750.0,4239720.0,249.0,1.14,1.63,2.4402,868988.0,23.0219,2.06842,1.14,2.14053
PS-S20,296.15,-1665.24248,-163.68,-6.18,6.76,1.0,-1.16,24.0,280.97,266.6,197.82,-222.78,36.91,3.6,36.776,1.4,202.02,61.81,587.93,-1665.00384,197.4,438.59,-1665.05876,1.9,1.77,0.885,1650.0,420.0,1120.0,5697530.0,209.0,2.86,1.68,2.0482,833167.0,23.5263,4.85971,2.86,0.716154